<?xml version="1.0" ?>
<!-- =================================================================================== -->
<!-- |    This document was autogenerated by xacro from elir.urdf.xacro                | -->
<!-- |    EDITING THIS FILE BY HAND IS NOT RECOMMENDED                                 | -->
<!-- =================================================================================== -->
<robot name="elir_robot" xmlns:controller="http://playerstage.sourceforge.net/gazebo/xmlschema/#controller" xmlns:interface="http://playerstage.sourceforge.net/gazebo/xmlschema/#interface" xmlns:sensor="http://playerstage.sourceforge.net/gazebo/xmlschema/#sensor" xmlns:xacro="http://www.ros.org/wiki/xacro">
  <material name="black">
    <color rgba="0.0 0.0 0.0 1.0"/>
  </material>
  <material name="blue">
    <color rgba="0.0 0.0 0.8 1.0"/>
  </material>
  <material name="green">
    <color rgba="0.0 0.8 0.0 1.0"/>
  </material>
  <material name="grey">
    <color rgba="0.2 0.2 0.2 1.0"/>
  </material>
  <material name="orange">
    <color rgba="1.0 0.423529411765 0.0392156862745 1.0"/>
  </material>
  <material name="brown">
    <color rgba="0.870588235294 0.811764705882 0.764705882353 1.0"/>
  </material>
  <material name="red">
    <color rgba="0.8 0.0 0.0 1.0"/>
  </material>
  <material name="white">
    <color rgba="1.0 1.0 1.0 1.0"/>
  </material>
  <material name="silver">
    <color rgba="0.870588235294 1.0 0.996078431373 1.0"/>
  </material>
  <gazebo>
    <plugin filename="libgazebo_ros_control.so" name="gazebo_ros_control">
      <robotNamespace>/robot</robotNamespace>
      <robotSimType>gazebo_ros_control/DefaultRobotHWSim</robotSimType>
    </plugin>
  </gazebo>
  <!-- Base link-->
  <gazebo reference="base_link">
    <dampingFactor>0.01</dampingFactor>
    <material name="grey"/>
    <self_collide>true</self_collide>
  </gazebo>
  <!-- Link1 -->
  <gazebo reference="link1_f">
    <dampingFactor>0.01</dampingFactor>
    <material name="grey"/>
  </gazebo>
  <gazebo reference="link1_t">
    <dampingFactor>0.01</dampingFactor>
    <material name="grey"/>
  </gazebo>
  <!-- Tracao -->
  <gazebo reference="tracao_f">
    <dampingFactor>0.01</dampingFactor>
    <material name="grey"/>
  </gazebo>
  <gazebo reference="tracao_b">
    <dampingFactor>0.01</dampingFactor>
    <material name="grey"/>
  </gazebo>
  <!-- Garras -->
  <gazebo reference="garra_ap">
    <dampingFactor>0.02</dampingFactor>
    <material name="grey"/>
  </gazebo>
  <gazebo reference="garra_tracao_f1">
    <dampingFactor>0.02</dampingFactor>
    <material name="grey"/>
  </gazebo>
  <gazebo reference="garra_tracao_f2">
    <dampingFactor>0.02</dampingFactor>
    <material name="grey"/>
  </gazebo>
  <gazebo reference="garra_tracao_b1">
    <dampingFactor>0.02</dampingFactor>
    <material name="grey"/>
  </gazebo>
  <gazebo reference="garra_tracao_b2">
    <dampingFactor>0.02</dampingFactor>
    <material name="grey"/>
  </gazebo>
  <!-- Eixos -->
  <gazebo reference="eixo_tracao_ap">
    <mu1>0.3</mu1>
    <mu2>0.3</mu2>
    <material name="black"/>
  </gazebo>
  <gazebo reference="eixo_tracao_f1">
    <mu1>0.3</mu1>
    <mu2>0.3</mu2>
    <material name="black"/>
  </gazebo>
  <gazebo reference="eixo_tracao_f2">
    <mu1>0.3</mu1>
    <mu2>0.3</mu2>
    <material name="black"/>
  </gazebo>
  <gazebo reference="eixo_tracao_b1">
    <mu1>0.3</mu1>
    <mu2>0.3</mu2>
    <material name="black"/>
  </gazebo>
  <gazebo reference="eixo_tracao_b2">
    <mu1>0.3</mu1>
    <mu2>0.3</mu2>
    <material name="black"/>
  </gazebo>
  <gazebo reference="zed_left_camera">
    <sensor name="zed_left_camera" type="camera">
      <update_rate>30.0</update_rate>
      <camera name="head">
        <horizontal_fov>1.3962634</horizontal_fov>
        <image>
          <width>800</width>
          <height>800</height>
          <format>R8G8B8</format>
        </image>
        <clip>
          <near>0.02</near>
          <far>300</far>
        </clip>
        <noise>
          <type>gaussian</type>
          <mean>0.0</mean>
          <stddev>0.007</stddev>
        </noise>
      </camera>
      <plugin filename="libgazebo_ros_camera.so" name="camera_controller">
        <alwaysOn>true</alwaysOn>
        <updateRate>0.0</updateRate>
        <cameraName>detection/zed_left_camera</cameraName>
        <imageTopicName>image_raw</imageTopicName>
        <cameraInfoTopicName>camera_info</cameraInfoTopicName>
        <frameName>camera_link</frameName>
        <hackBaseline>0.07</hackBaseline>
        <distortionK1>0.0</distortionK1>
        <distortionK2>0.0</distortionK2>
        <distortionK3>0.0</distortionK3>
        <distortionT1>0.0</distortionT1>
        <distortionT2>0.0</distortionT2>
      </plugin>
    </sensor>
  </gazebo>
  <gazebo reference="zed_right_camera">
    <sensor name="zed_right_camera" type="camera">
      <update_rate>30.0</update_rate>
      <camera name="head">
        <horizontal_fov>1.3962634</horizontal_fov>
        <image>
          <width>800</width>
          <height>800</height>
          <format>R8G8B8</format>
        </image>
        <clip>
          <near>0.02</near>
          <far>300</far>
        </clip>
        <noise>
          <type>gaussian</type>
          <mean>0.0</mean>
          <stddev>0.007</stddev>
        </noise>
      </camera>
      <plugin filename="libgazebo_ros_camera.so" name="camera_controller">
        <alwaysOn>true</alwaysOn>
        <updateRate>0.0</updateRate>
        <cameraName>detection/zed_right_camera</cameraName>
        <imageTopicName>image_raw</imageTopicName>
        <cameraInfoTopicName>camera_info</cameraInfoTopicName>
        <frameName>camera_link</frameName>
        <hackBaseline>0.07</hackBaseline>
        <distortionK1>0.0</distortionK1>
        <distortionK2>0.0</distortionK2>
        <distortionK3>0.0</distortionK3>
        <distortionT1>0.0</distortionT1>
        <distortionT2>0.0</distortionT2>
      </plugin>
    </sensor>
  </gazebo>
  <gazebo reference="ground_sonar">
    <sensor name="ground_sonar" type="ray">
      <always_on>true</always_on>
      <update_rate>30</update_rate>
      <pose>0 0 0 0 0 0</pose>
      <visualize>false</visualize>
      <ray>
        <scan>
          <horizontal>
            <samples>1</samples>
            <resolution>1</resolution>
            <min_angle>-0.52355</min_angle>
            <max_angle> 0.52355</max_angle>
          </horizontal>
          <vertical>
            <samples>1</samples>
            <resolution>1</resolution>
            <min_angle>-0.52355</min_angle>
            <max_angle> 0.52355</max_angle>
          </vertical>
        </scan>
        <range>
          <min>0.1</min>
          <max>100</max>
          <resolution>0.01</resolution>
        </range>
      </ray>
      <plugin filename="libhector_gazebo_ros_sonar.so" name="gazebo_ros_ground_sonar_controller">
        <gaussianNoise>0.005</gaussianNoise>
        <topicName>perception/ground_sonar</topicName>
        <frameId>ground_sonar</frameId>
      </plugin>
    </sensor>
  </gazebo>
  <gazebo reference="flir_camera">
    <sensor name="thermal_camera_sensor" type="camera">
      <update_rate>30</update_rate>
      <camera>
        <horizontal_fov>0.890117733333</horizontal_fov>
        <image>
          <format>R8G8B8</format>
          <width>60</width>
          <height>80</height>
        </image>
        <clip>
          <near>0.1</near>
          <far>300</far>
        </clip>
      </camera>
      <plugin filename="libgazebo_ros_thermal_camera.so" name="thermal_camera_controller">
        <alwaysOn>true</alwaysOn>
        <updateRate>8.6</updateRate>
        <imageTopicName>/perception/flir_camera/image_raw</imageTopicName>
        <cameraInfoTopicName>/perception/flir_camera/camera_info</cameraInfoTopicName>
        <frameName>flir_camera_optical_frame</frameName>
      </plugin>
    </sensor>
  </gazebo>
  <!-- Parametros do box_link-->
  <link name="base_link">
  </link>
  <joint name="base_joint" type="fixed">
    <origin rpy="0.0 0.0 0.0" xyz="0.0 0.0 0.11785"/>
    <parent link="base_link"/>
    <child link="box_link"/>
    <axis xyz="0.0 0.0 0.0"/>
    <limit effort="0.0" lower="0.0" upper="0.0" velocity="0.0"/>
  </joint>
  <!-- This link represents the base body of the robot, the central stem and the central's claw base -->
  <link name="box_link">
    <!-- This visual represents the base body-->
    <visual name="base_body">
      <geometry>
        <box size="0.3219 0.1461 0.2357"/>
      </geometry>
      <material name="silver"/>
    </visual>
    <!-- This visual represents the central stem -->
    <visual name="central_stem">
      <geometry>
        <box size="0.0367 0.0367 0.279"/>
      </geometry>
      <material name="silver"/>
      <!-- <xacro:insert_block name="a.test_central_stem_origin" /> -->
      <origin rpy="0 0 0" xyz="0 0.0303 0.23365"/>
    </visual>
    <!-- This visual represents the claw's base in the central stem -->
    <!-- Need to check mesh design to see if dimensions is the same as the actual dimensions of elir -->
    <visual name="central_claw_base">
      <geometry>
        <box size="0.051 0.045 0.036 "/>
      </geometry>
      <material name="black"/>
      <origin rpy="0 0 0" xyz="0.0 0.0722 0.3554"/>
    </visual>
    <!-- This collision is for the base_body -->
    <collision name="base_body">
      <geometry>
        <box size="0.3219 0.1461 0.2357"/>
      </geometry>
      <origin rpy="0 0 0" xyz="0.0 0.0 0"/>
    </collision>
    <!-- This collision is for the central_stem -->
    <collision name="central_stem">
      <geometry>
        <box size="0.0367 0.0367 0.279"/>
      </geometry>
      <origin rpy="0 0 0" xyz="0 0.0303 0.23365"/>
    </collision>
    <!-- This collision is for the central_claw_base -->
    <collision name="central_claw_base">
      <geometry>
        <box size="0.051 0.045 0.036 "/>
      </geometry>
      <origin rpy="0 0 0" xyz="0.0 0.0722 0.3554"/>
    </collision>
    <inertial>
      <origin rpy="0 0 0" xyz="-0.00588 0.001 0.0171"/>
      <mass value="4.565"/>
      <inertia ixx="9.8478" ixy="-0.0181" ixz="-0.0877" iyy="15.5246" iyz="-0.5623" izz="9.2774"/>
    </inertial>
  </link>
  <!-- this joint binds the base body (represented by the link box_link) with the central claw unit (represented by the link garra_ap). It can rotate with the z axis fixed, it has an upper limit of 3,14 (180 degrees) and a lower limit of -3,14 (-180 degrees) -->
  <joint name="joint_garra_ap" type="revolute">
    <parent link="box_link"/>
    <child link="garra_ap"/>
    <origin rpy="0 0 3.141592" xyz="0.0 0.0722 0.3554"/>
    <limit effort="1000.0" lower="-3.14" upper="3.14" velocity="0.5"/>
    <axis xyz="0 0 1"/>
  </joint>
  <!-- this link represents the central claw unit -->
  <link name="garra_ap">
    <!-- This visual represents the central claw unit -->
    <!-- Need to check mesh design to see if dimensions is the same as the actual dimensions of elir -->
    <visual name="central_claw">
      <geometry>
        <mesh filename="package://elir_description/meshes/claw.dae"/>
      </geometry>
      <material name="silver"/>
    </visual>
    <!-- This collision is for the central claw unit -->
    <collision name="central_claw">
      <geometry>
        <mesh filename="package://elir_description/meshes/claw.dae"/>
      </geometry>
    </collision>
    <inertial>
      <origin rpy="0 0 0" xyz="0.0 0.015953 0.116844"/>
      <mass value="0.22"/>
      <inertia ixx="0.000598" ixy="0.0" ixz="0.0" iyy="0.000866" iyz="0.000169" izz="0.000866"/>
    </inertial>
  </link>
  <!-- this joint binds the central claw unit (represented by the link garra_ap) with the central traction unit (represented by the link eixo_tracao_ap). It can move contunuously with the y axis fixed. It moves forward and backward -->
  <joint name="joint_eixo_tracao_ap" type="continuous">
    <parent link="garra_ap"/>
    <child link="eixo_tracao_ap"/>
    <origin rpy="0 0 0" xyz="0.0 0.058 0.172"/>
    <axis xyz="0 1 0"/>
    <dynamics damping="0.7" friction="1.0"/>
  </joint>
  <!-- this link represents the central traction unit -->
  <link name="eixo_tracao_ap">
    <!-- This visual represents the central traction unit -->
    <!-- Need to check mesh design to see if dimensions is the same as the actual dimensions of elir -->
    <visual name="central_traction">
      <geometry>
        <mesh filename="package://elir_description/meshes/wheel_elir.STL" scale="0.001 0.001 0.001"/>
      </geometry>
      <origin rpy="0 0 0" xyz="-0.03 0 -0.03"/>
    </visual>
    <!-- This collision is for the central traction unit -->
    <collision name="central_traction">
      <geometry>
        <mesh filename="package://elir_description/meshes/wheel_elir.STL" scale="0.001 0.001 0.001"/>
      </geometry>
      <origin rpy="0 0 0" xyz="-0.03 0 -0.03"/>
    </collision>
    <inertial>
      <origin rpy="0 0 0" xyz="0.0 0.026065 0.0"/>
      <mass value="0.1"/>
      <inertia ixx="4.94e-05" ixy="0.0" ixz="0.0" iyy="6.11e-05" iyz="0.0" izz="4.94e-05"/>
    </inertial>
  </link>
  <!-- This joint binds the base body (represented by the link box_link) and the front arm unit (represented by the link link1_f). it can rotate with the y axis fixed, it has an upper limit of 0.7 (40 degrees) and a lower limit of -1.74 (-100 degrees) -->
  <joint name="joint1_b" type="revolute">
    <parent link="box_link"/>
    <child link="link1_b"/>
    <!-- <origin rpy=" 0 -0.60 3.141592" xyz="-0.13 0.0 0.079"/> -->
    <origin rpy=" 0 -0.6 3.141592" xyz="-0.13 0.0 0.079"/>
    <limit effort="1000.0" lower="-1.74" upper="0.7" velocity="0.5"/>
    <axis xyz="0 1 0"/>
  </joint>
  <!-- This link represents the front arm unit  -->
  <link name="link1_b">
    <!-- <visual>
      <geometry>
        <box size="0.185 0.102 0.102"/>
      </geometry>
      <material name="silver"/>
      <origin rpy="0 0 0" xyz="0.1985 0.0 0.0"/>
    </visual> -->
    <!-- This visual represents the front arm unit -->
    <visual name="back_arm">
      <geometry>
        <box size="0.19 0.100 0.05"/>
      </geometry>
      <material name="silver"/>
      <origin rpy="0 0 0" xyz="0.20995 0.0 0.0"/>
    </visual>
    <visual name="base_left_pallet">
      <geometry>
        <mesh filename="package://elir_description/meshes/PIR-M01-003-0_HolderWingWide.STL" scale="0.001 0.001 0.001"/>
      </geometry>
      <material name="black"/>
      <origin rpy="1.570796 0 0" xyz="0 0.085 -0.025"/>
    </visual>
    <visual name="base_right_pallet">
      <geometry>
        <mesh filename="package://elir_description/meshes/PIR-M01-003-0_HolderWingWide.STL" scale="0.001 0.001 0.001"/>
      </geometry>
      <material name="black"/>
      <origin rpy="-1.570796 0 0" xyz="0 -0.085 0.025"/>
    </visual>
    <visual name="traction_left_pallet">
      <geometry>
        <mesh filename="package://elir_description/meshes/PIR-M01-002-0_HolderWing.STL" scale="0.001 0.001 0.001"/>
      </geometry>
      <material name="black"/>
      <origin rpy="1.570796 -3.141592 0" xyz="0.4199 0.06 0.025"/>
    </visual>
    <visual name="traction_right_pallet">
      <geometry>
        <mesh filename="package://elir_description/meshes/PIR-M01-002-0_HolderWing.STL" scale="0.001 0.001 0.001"/>
      </geometry>
      <material name="black"/>
      <origin rpy="-1.570796 -3.141592 0" xyz="0.4199 -0.06 -0.025"/>
    </visual>
    <!-- this collision is for the front arm unit -->
    <collision name="back_arm">
      <geometry>
        <box size="0.19 0.100 0.05"/>
      </geometry>
      <origin rpy="0 0 0" xyz="0.20995 0.0 0.0"/>
    </collision>
    <inertial>
      <origin rpy="0 0 0" xyz="-0.09625 0.08644 0.00657"/>
      <mass value="0.386"/>
      <inertia ixx="0.3971" ixy="0.0" ixz="0.0" iyy="2.2533" iyz="0.0" izz="2.3067"/>
    </inertial>
  </link>
  <!-- This joint binds the base body (represented by the link box_link) and the back arm unit (represented by the link link1_t). it can rotate with the y axis fixed, it has an upper limit of 0.7 (40 degrees) and a lower limit of -1.74 (-100 degrees) -->
  <joint name="joint1_f" type="revolute">
    <parent link="box_link"/>
    <child link="link1_f"/>
    <!-- <origin rpy="0 -0.60 0" xyz="0.13 0.0 0.079"/> -->
    <origin rpy=" 0 -0.6 0" xyz="0.13 0.0 0.079"/>
    <limit effort="1000.0" lower="-1.74" upper="0.7" velocity="0.5"/>
    <axis xyz="0 1 0"/>
  </joint>
  <!-- This link represents the back arm unit  -->
  <link name="link1_f">
    <!-- <visual>
      <geometry>
        <box size="0.185 0.102 0.102"/>
      </geometry>
      <material name="silver"/>
      <origin rpy="0 0 0" xyz="0.1985 0.0 0.0"/>
    </visual> -->
    <!-- This visual represents the back arm unit -->
    <visual name="front_arm">
      <geometry>
        <box size="0.19 0.100 0.05"/>
      </geometry>
      <material name="silver"/>
      <origin rpy="0 0 0" xyz="0.20995 0.0 0.0"/>
    </visual>
    <!-- this collision is for the back arm unit -->
    <visual name="base_left_pallet">
      <geometry>
        <mesh filename="package://elir_description/meshes/PIR-M01-003-0_HolderWingWide.STL" scale="0.001 0.001 0.001"/>
      </geometry>
      <material name="black"/>
      <origin rpy="1.570796 0 0" xyz="0 0.085 -0.025"/>
    </visual>
    <visual name="base_right_pallet">
      <geometry>
        <mesh filename="package://elir_description/meshes/PIR-M01-003-0_HolderWingWide.STL" scale="0.001 0.001 0.001"/>
      </geometry>
      <material name="black"/>
      <origin rpy="-1.570796 0 0" xyz="0 -0.085 0.025"/>
    </visual>
    <visual name="traction_left_pallet">
      <geometry>
        <mesh filename="package://elir_description/meshes/PIR-M01-002-0_HolderWing.STL" scale="0.001 0.001 0.001"/>
      </geometry>
      <material name="black"/>
      <origin rpy="1.570796 -3.141592 0" xyz="0.4199 0.06 0.025"/>
    </visual>
    ]

    
    <visual name="traction_right_pallet">
      <geometry>
        <mesh filename="package://elir_description/meshes/PIR-M01-002-0_HolderWing.STL" scale="0.001 0.001 0.001"/>
      </geometry>
      <material name="black"/>
      <origin rpy="-1.570796 -3.141592 0" xyz="0.4199 -0.06 -0.025"/>
    </visual>
    <collision name="front_arm">
      <geometry>
        <box size="0.19 0.100 0.05"/>
      </geometry>
      <origin rpy="0 0 0" xyz="0.20995 0.0 0.0"/>
    </collision>
    <inertial>
      <origin rpy="0 0 0" xyz="-0.09625 0.08644 0.00657"/>
      <mass value="0.386"/>
      <inertia ixx="0.3971" ixy="0.0" ixz="0.0" iyy="2.2533" iyz="0.0" izz="2.3067"/>
    </inertial>
  </link>
  <!-- This joint binds the front arm unit (represented by the link link1_f) and the front traction body unit (represented by the link tracao_f). It can rotate with the y axis fixed, it has an upper limit of 2.18 (125 degrees) and a lower limit of -1.0 (-57 degrees) -->
  <joint name="joint2_f" type="revolute">
    <parent link="link1_f"/>
    <child link="tracao_f"/>
    <origin rpy="0 0.57 0" xyz="0.39 0.0 0.0"/>
    <limit effort="1000.0" lower="-1.0" upper="2.18" velocity="0.5"/>
    <axis xyz="0 1 0"/>
  </joint>
  <!-- This link represents the front traction body unit that contains front traction body, claw f1 support and claw f2 support -->
  <link name="tracao_f">
    <!-- This visual represents the front traction body -->
    <visual name="front_traction_body">
      <geometry>
        <box size="0.233 0.100 0.100"/>
      </geometry>
      <material name="silver"/>
      <origin rpy="0 0 0" xyz="0.1165 0.0 0.0201"/>
    </visual>
    <!-- This visual represents the front traction claw f2 support -->
    <!-- Need to check mesh design to see if dimensions is the same as the actual dimensions of elir -->
    <visual name="front_traction_claw_f1_support">
      <geometry>
        <box size="0.051 0.045 0.036 "/>
      </geometry>
      <material name="grey"/>
      <origin rpy="0 0 0" xyz="0.0315 0.0725 0.05"/>
    </visual>
    <!-- This visual represents the front traction claw f1 support -->
    <!-- Need to check mesh design to see if dimensions is the same as the actual dimensions of elir -->
    <visual name="front_traction_claw_f2_support">
      <geometry>
        <box size="0.051 0.045 0.036 "/>
      </geometry>
      <material name="grey"/>
      <origin rpy="0 0 0" xyz="0.2015 -0.0725 0.05"/>
    </visual>
    <!-- this collision is for the front traction body -->
    <collision name="front_traction_body">
      <geometry>
        <box size="0.233 0.100 0.100"/>
      </geometry>
      <origin rpy="0 0 0" xyz="0.1165 0.0 0.0201"/>
    </collision>
    <!-- this collision is for the front traction claw f2 support -->
    <collision name="front_traction_claw_f2_support">
      <geometry>
        <box size="0.051 0.045 0.036 "/>
      </geometry>
      <origin rpy="0 0 0" xyz="0.0005 0.075 0.0521"/>
    </collision>
    <!-- this collision is for the front traction claw f1 support -->
    <collision name="front_traction_claw_f1_support">
      <geometry>
        <box size="0.051 0.045 0.036 "/>
      </geometry>
      <origin rpy="0 0 3.141592" xyz="0.1765 -0.075 0.0521"/>
    </collision>
    <inertial>
      <origin rpy="0 0 0" xyz="0.03499 0.0 0.0"/>
      <mass value="0.792"/>
      <inertia ixx="0.5622" ixy="0.161" ixz="0.0008" iyy="1.0746" iyz="0.0" izz="1.2126"/>
    </inertial>
  </link>
  <!-- This joint binds the back arm unit (represented by the link link1_t) and the back traction body unit (represented by the link tracao_b). It can rotate with the y axis fixed, it has an upper limit of 2.18 (125 degrees) and a lower limit of -1.0 (-57 degrees) -->
  <joint name="joint2_b" type="revolute">
    <parent link="link1_b"/>
    <child link="tracao_b"/>
    <origin rpy="0 0.57 0" xyz="0.39 0.0 0.0"/>
    <limit effort="1000.0" lower="-1.0" upper="2.18" velocity="0.5"/>
    <axis xyz="0 1 0"/>
  </joint>
  <!-- This link represents the back traction body unit that contains back traction body, claw f1 support and claw f2 support -->
  <link name="tracao_b">
    <!-- This visual represents the  back traction body -->
    <visual name="back_traction_body">
      <geometry>
        <box size="0.233 0.100 0.100"/>
      </geometry>
      <material name="silver"/>
      <origin rpy="0 0 0" xyz="0.1165 0.0 0.0201"/>
    </visual>
    <!-- This visual represents the  back traction claw f1 support -->
    <visual name="back_traction_claw_f1_support">
      <geometry>
        <box size="0.051 0.045 0.036 "/>
      </geometry>
      <material name="grey"/>
      <origin rpy="0 0 0" xyz="0.0315 0.0725 0.05"/>
    </visual>
    <!-- This visual represents the  back traction claw f2 support -->
    <visual name="back_traction_claw_f2_support">
      <geometry>
        <box size="0.051 0.045 0.036 "/>
      </geometry>
      <material name="grey"/>
      <origin rpy="0 0 0" xyz="0.2015 -0.0725 0.05"/>
    </visual>
    <!-- this collision is for the back traction body -->
    <collision name="back_traction_body">
      <geometry>
        <box size="0.233 0.100 0.100"/>
      </geometry>
      <origin rpy="0 0 0" xyz="0.1165 0.0 0.0201"/>
    </collision>
    <!-- this collision is for the back traction claw f1 support -->
    <collision name="back_traction_claw_f1_support">
      <geometry>
        <box size="0.051 0.045 0.036 "/>
      </geometry>
      <origin rpy="0 0 0" xyz="0.0005 -0.075 0.0521"/>
    </collision>
    <!-- this collision is for the back traction claw f2 support -->
    <collision name="back_traction_claw_f2_support">
      <geometry>
        <box size="0.051 0.045 0.036 "/>
      </geometry>
      <origin rpy="0 0 3.141592" xyz="0.1765 0.075 0.0521"/>
    </collision>
    <inertial>
      <origin rpy="0 0 0" xyz="0.03499 0.0 0.0"/>
      <mass value="0.792"/>
      <inertia ixx="0.5622" ixy="0.161" ixz="0.0008" iyy="1.0746" iyz="0.0" izz="1.2126"/>
    </inertial>
  </link>
  <!-- This joint binds the front traction body unit (represented by the link tracao_f) and the front f1 claw unit (represented by the link garra_tracao_f1). It can rotate with the z axis fixed, it has an upper limit of 3.14 (360 degrees) and lower limit of -3.14 (-360 degrees) -->
  <joint name="joint_garra_tracao_f1" type="revolute">
    <parent link="tracao_f"/>
    <child link="garra_tracao_f1"/>
    <origin rpy="0 0 3.141592" xyz="0.017 0.078 0.0725"/>
    <limit effort="1000.0" lower="-3.14" upper="3.14" velocity="0.5"/>
    <axis xyz="0 0 1"/>
  </joint>
  <!-- this link represents the front f1 claw unit -->
  <link name="garra_tracao_f1">
    <!-- Need to check mesh design to see if dimensions is the same as the actual dimensions of elir -->
    <!-- This visual represents the front f1 claw unit -->
    <visual>
      <geometry>
        <mesh filename="package://elir_description/meshes/claw.dae"/>
      </geometry>
      <material name="silver"/>
      <origin rpy="0 0 0" xyz="0.0 0.0 0.0"/>
    </visual>
    <!-- this collision is for the front f1 claw unit -->
    <collision>
      <geometry>
        <mesh filename="package://elir_description/meshes/claw.dae"/>
      </geometry>
      <origin rpy="0 0 0" xyz="0.0 0.0 0.0"/>
    </collision>
    <inertial>
      <origin rpy="0 0 0" xyz="0.0 0.015953 0.116844"/>
      <mass value="0.22"/>
      <inertia ixx="0.000598" ixy="0.0" ixz="0.0" iyy="0.000866" iyz="0.000169" izz="0.000866"/>
    </inertial>
  </link>
  <!-- this joint binds the front f1 claw unit (represented by the link garra_tracao_f1) with the front f1 traction unit (represented by the link eixo_tracao_f1). It can move contunuously with the y axis fixed. It moves forward and backward -->
  <joint name="joint_eixo_tracao_f1" type="continuous">
    <parent link="garra_tracao_f1"/>
    <child link="eixo_tracao_f1"/>
    <origin rpy="0 0 0" xyz="0.0 0.058 0.172"/>
    <axis xyz="0 1 0"/>
    <dynamics damping="0.7" friction="1.0"/>
  </joint>
  <!-- this link represents the front f1 traction unit -->
  <link name="eixo_tracao_f1">
    <!-- This visual represents the front f1 traction unit -->
    <!-- Need to check mesh design to see if dimensions is the same as the actual dimensions of elir -->
    <visual>
      <geometry>
        <mesh filename="package://elir_description/meshes/wheel_elir.STL" scale="0.001 0.001 0.001"/>
      </geometry>
      <material name="silver"/>
      <origin rpy="0 0 0" xyz="-0.03 0 -0.0305"/>
    </visual>
    <!-- This collision is for the front f1 traction unit -->
    <collision>
      <geometry>
        <mesh filename="package://elir_description/meshes/wheel_elir.STL" scale="0.001 0.001 0.001"/>
      </geometry>
      <origin rpy="0 0 0" xyz="-0.03 0 -0.03"/>
    </collision>
    <inertial>
      <origin rpy="0 0 0" xyz="0.0 0.026065 0.0"/>
      <mass value="0.1"/>
      <inertia ixx="4.94e-05" ixy="0.0" ixz="0.0" iyy="6.11e-05" iyz="0.0" izz="4.94e-05"/>
    </inertial>
  </link>
  <!-- This joint binds the front traction body unit (represented by the link tracao_f) and the front f2 claw unit (represented by the link garra_tracao_f2). It can rotate with the z axis fixed, it has an upper limit of 3.14 (360 degrees) and lower limit of -3.14 (-360 degrees) -->
  <joint name="joint_garra_tracao_f2" type="revolute">
    <parent link="tracao_f"/>
    <child link="garra_tracao_f2"/>
    <origin rpy="0 0 0" xyz="0.216 -0.078 0.0725"/>
    <limit effort="1000.0" lower="-3.14" upper="3.14" velocity="0.5"/>
    <axis xyz="0 0 1"/>
  </joint>
  <!-- this link represents the front f2 claw unit -->
  <link name="garra_tracao_f2">
    <!-- Need to check mesh design to see if dimensions is the same as the actual dimensions of elir -->
    <!-- This visual represents the front f2 claw unit -->
    <visual>
      <geometry>
        <mesh filename="package://elir_description/meshes/claw.dae"/>
      </geometry>
      <material name="silver"/>
      <origin rpy="0 0 0" xyz="0.0 0.0 0.0"/>
    </visual>
    <!-- this collision is for the front f2 claw unit -->
    <collision>
      <geometry>
        <mesh filename="package://elir_description/meshes/claw.dae"/>
      </geometry>
      <origin rpy="0 0 0" xyz="0.0 0.0 0.0"/>
    </collision>
    <inertial>
      <origin rpy="0 0 0" xyz="0.0 0.015953 0.116844"/>
      <mass value="0.22"/>
      <inertia ixx="0.000598" ixy="0.0" ixz="0.0" iyy="0.000866" iyz="0.000169" izz="0.000866"/>
    </inertial>
  </link>
  <!-- this joint binds the front f2 claw unit (represented by the link garra_tracao_f2) with the front f2 traction unit (represented by the link eixo_tracao_f2). It can move contunuously with the y axis fixed. It moves forward and backward -->
  <joint name="joint_eixo_tracao_f2" type="continuous">
    <parent link="garra_tracao_f2"/>
    <child link="eixo_tracao_f2"/>
    <origin rpy="0 0 0" xyz="0.0 0.058 0.172"/>
    <axis xyz="0 1 0"/>
    <dynamics damping="0.7" friction="1.0"/>
  </joint>
  <!-- this link represents the front f2 traction unit -->
  <link name="eixo_tracao_f2">
    <!-- This visual represents the front f2 traction unit -->
    <!-- Need to check mesh design to see if dimensions is the same as the actual dimensions of elir -->
    <visual>
      <geometry>
        <mesh filename="package://elir_description/meshes/wheel_elir.STL" scale="0.001 0.001 0.001"/>
      </geometry>
      <material name="silver"/>
      <origin rpy="0 0 0" xyz="-0.03 0 -0.03"/>
    </visual>
    <!-- This collision is for the front f2 traction unit -->
    <collision>
      <geometry>
        <mesh filename="package://elir_description/meshes/wheel_elir.STL" scale="0.001 0.001 0.001"/>
      </geometry>
      <origin rpy="0 0 0" xyz="-0.03 0 -0.03"/>
    </collision>
    <inertial>
      <origin rpy="0 0 0" xyz="0.0 0.026065 0.0"/>
      <mass value="0.1"/>
      <inertia ixx="4.94e-05" ixy="0.0" ixz="0.0" iyy="6.11e-05" iyz="0.0" izz="4.94e-05"/>
    </inertial>
  </link>
  <!-- GARRAS TRACAO TRASEIRA -->
  <!-- T1 -->
  <!-- This joint binds the front traction body unit (represented by the link tracao_f) and the back t1 claw unit (represented by the link garra_tracao_b1). It can rotate with the z axis fixed, it has an upper limit of 3.14 (360 degrees) and lower limit of -3.14 (-360 degrees) -->
  <joint name="joint_garra_tracao_b1" type="revolute">
    <parent link="tracao_b"/>
    <child link="garra_tracao_b1"/>
    <origin rpy="0 0 3.141592" xyz="0.017 0.078 0.0725"/>
    <limit effort="1000.0" lower="-3.14" upper="3.14" velocity="0.5"/>
    <axis xyz="0 0 1"/>
  </joint>
  <!-- this link represents the back t1 claw unit -->
  <link name="garra_tracao_b1">
    <!-- Need to check mesh design to see if dimensions is the same as the actual dimensions of elir -->
    <!-- This visual represents the back t1 claw unit -->
    <visual>
      <geometry>
        <mesh filename="package://elir_description/meshes/claw.dae"/>
      </geometry>
      <material name="silver"/>
      <origin rpy="0 0 0" xyz="0.0 0.0 0.0"/>
    </visual>
    <!-- this collision is for the back t1 claw unit -->
    <collision>
      <geometry>
        <mesh filename="package://elir_description/meshes/claw.dae"/>
      </geometry>
      <origin rpy="0 0 0" xyz="0.0 0.0 0.0"/>
    </collision>
    <inertial>
      <origin rpy="0 0 0" xyz="0.0 0.015953 0.116844"/>
      <mass value="0.22"/>
      <inertia ixx="0.000598" ixy="0.0" ixz="0.0" iyy="0.000866" iyz="0.000169" izz="0.000866"/>
    </inertial>
  </link>
  <!-- Eixo T1 -->
  <!-- this joint binds the back t1 claw unit (represented by the link garra_tracao_b1) with the back t1 traction unit (represented by the link eixo_tracao_b1). It can move contunuously with the y axis fixed. It moves forward and backward -->
  <joint name="joint_eixo_tracao_b1" type="continuous">
    <parent link="garra_tracao_b1"/>
    <child link="eixo_tracao_b1"/>
    <origin rpy="0 0 0" xyz="0.0 0.058 0.172"/>
    <axis xyz="0 1 0"/>
    <dynamics damping="0.7" friction="1.0"/>
  </joint>
  <!-- this link represents the back t1 traction unit -->
  <link name="eixo_tracao_b1">
    <!-- This visual represents the back t1 traction unit -->
    <!-- Need to check mesh design to see if dimensions is the same as the actual dimensions of elir -->
    <visual>
      <geometry>
        <mesh filename="package://elir_description/meshes/wheel_elir.STL" scale="0.001 0.001 0.001"/>
      </geometry>
      <material name="silver"/>
      <origin rpy="0 0 0" xyz="-0.03 0 -0.03"/>
    </visual>
    <!-- This collision is for the back t1 traction unit -->
    <collision>
      <geometry>
        <mesh filename="package://elir_description/meshes/wheel_elir.STL" scale="0.001 0.001 0.001"/>
      </geometry>
      <origin rpy="0 0 0" xyz="-0.03 0 -0.03"/>
    </collision>
    <inertial>
      <origin rpy="0 0 0" xyz="0.0 0.026065 0.0"/>
      <mass value="0.1"/>
      <inertia ixx="4.94e-05" ixy="0.0" ixz="0.0" iyy="6.11e-05" iyz="0.0" izz="4.94e-05"/>
    </inertial>
  </link>
  <!-- T2 -->
  <!-- This joint binds the front traction body unit (represented by the link tracao_f) and the back t2 claw unit (represented by the link garra_tracao_b2). It can rotate with the z axis fixed, it has an upper limit of 3.14 (360 degrees) and lower limit of -3.14 (-360 degrees) -->
  <joint name="joint_garra_tracao_b2" type="revolute">
    <parent link="tracao_b"/>
    <child link="garra_tracao_b2"/>
    <origin rpy="0 0 0" xyz="0.216 -0.078 0.0725"/>
    <limit effort="1000.0" lower="-3.14" upper="3.14" velocity="0.5"/>
    <axis xyz="0 0 1"/>
  </joint>
  <!-- this link represents the back t2 claw unit -->
  <link name="garra_tracao_b2">
    <!-- Need to check mesh design to see if dimensions is the same as the actual dimensions of elir -->
    <!-- This visual represents the back t2 claw unit -->
    <visual>
      <geometry>
        <mesh filename="package://elir_description/meshes/claw.dae"/>
      </geometry>
      <material name="silver"/>
      <origin rpy="0 0 0" xyz="0.0 0.0 0.0"/>
    </visual>
    <!-- this collision is for the back t2 claw unit -->
    <collision>
      <geometry>
        <mesh filename="package://elir_description/meshes/claw.dae"/>
      </geometry>
      <origin rpy="0 0 0" xyz="0.0 0.0 0.0"/>
    </collision>
    <inertial>
      <origin rpy="0 0 0" xyz="0.0 0.015953 0.116844"/>
      <mass value="0.22"/>
      <inertia ixx="0.000598" ixy="0.0" ixz="0.0" iyy="0.000866" iyz="0.000169" izz="0.000866"/>
    </inertial>
  </link>
  <!-- Eixo F2 -->
  <!-- this joint binds the back t2 claw unit (represented by the link garra_tracao_b2) with the back t2 traction unit (represented by the link eixo_tracao_b2). It can move contunuously with the y axis fixed. It moves forward and backward -->
  <joint name="joint_eixo_tracao_b2" type="continuous">
    <parent link="garra_tracao_b2"/>
    <child link="eixo_tracao_b2"/>
    <origin rpy="0 0 0" xyz="0.0 0.058 0.172"/>
    <axis xyz="0 1 0"/>
    <dynamics damping="0.7" friction="1.0"/>
  </joint>
  <!-- this link represents the back t2 traction unit -->
  <link name="eixo_tracao_b2">
    <!-- This visual represents the back t2 traction unit -->
    <!-- Need to check mesh design to see if dimensions is the same as the actual dimensions of elir -->
    <visual>
      <geometry>
        <mesh filename="package://elir_description/meshes/wheel_elir.STL" scale="0.001 0.001 0.001"/>
      </geometry>
      <material name="silver"/>
      <origin rpy="0 0 0" xyz="-0.03 0 -0.03"/>
    </visual>
    <!-- This collision is for the back t2 traction unit -->
    <collision>
      <geometry>
        <mesh filename="package://elir_description/meshes/wheel_elir.STL" scale="0.001 0.001 0.001"/>
      </geometry>
      <origin rpy="0 0 0" xyz="-0.03 0 -0.03"/>
    </collision>
    <inertial>
      <origin rpy="0 0 0" xyz="0.0 0.026065 0.0"/>
      <mass value="0.1"/>
      <inertia ixx="4.94e-05" ixy="0.0" ixz="0.0" iyy="6.11e-05" iyz="0.0" izz="4.94e-05"/>
    </inertial>
  </link>
  <link name="zed_left_camera">
    <visual>
      <origin rpy="0 1.57 0" xyz="0 0 0"/>
      <geometry>
        <cylinder length=".031" radius="0.007"/>
      </geometry>
      <material name="dark_grey">
        <color rgba="0.1 0.1 0.1 1"/>
      </material>
    </visual>
  </link>
  <link name="zed_center">
    <visual>
      <origin rpy="0 0 0" xyz="0 0 0"/>
      <geometry>
        <mesh filename="package://elir_description/meshes/ZED.stl"/>
      </geometry>
      <material name="light_grey">
        <color rgba="0.8 0.8 0.8 0.8"/>
      </material>
    </visual>
  </link>
  <link name="zed_right_camera">
    <visual>
      <origin rpy="0 1.57 0" xyz="0 0 0"/>
      <geometry>
        <cylinder length=".031" radius="0.007"/>
      </geometry>
      <material name="dark_grey">
        <color rgba="0.1 0.1 0.1 1"/>
      </material>
    </visual>
  </link>
  <link name="zed_depth_camera"/>
  <joint name="zed_left_camera_joint" type="fixed">
    <parent link="zed_center"/>
    <child link="zed_left_camera"/>
    <origin rpy="0 0 0" xyz="0 0.06 0"/>
  </joint>
  <joint name="zed_depth_camera_joint" type="fixed">
    <parent link="zed_left_camera"/>
    <child link="zed_depth_camera"/>
    <origin rpy="-1.5707963267948966 0 -1.5707963267948966" xyz="0 0 0"/>
  </joint>
  <joint name="zed_right_camera_joint" type="fixed">
    <parent link="zed_center"/>
    <child link="zed_right_camera"/>
    <origin rpy="0 0 0" xyz="0 -0.06 0"/>
  </joint>
  <link name="flir_camera">
    <visual>
      <origin rpy="0 1.570796 0" xyz="0 0 0"/>
      <geometry>
        <mesh filename="package://elir_description/meshes/LeptonBreakoutBoardWithLepton3.stl" scale="0.001 0.001 0.001"/>
      </geometry>
      <material name="light_grey">
        <color rgba="0.8 0.8 0.8 0.8"/>
      </material>
    </visual>
  </link>
  <joint name="zed_camera_joint" type="fixed">
    <parent link="box_link"/>
    <child link="zed_center"/>
    <origin rpy="0 0 0" xyz="0.17 0.0 -0.1"/>
  </joint>
  <joint name="flir_camera_joint" type="fixed">
    <parent link="box_link"/>
    <child link="flir_camera"/>
    <origin rpy="0 0 0" xyz="0.17 0.0 -0.05"/>
  </joint>
  <!-- Sonares -->
  <link name="ground_sonar">
    <visual>
      <geometry>
        <mesh filename="package://elir_description/meshes/groundsonar.dae"/>
      </geometry>
      <origin rpy="0 -1.570796 0"/>
    </visual>
    <collision>
      <geometry>
        <mesh filename="package://elir_description/meshes/groundsonar.dae"/>
      </geometry>
      <origin rpy="0 -1.570796 0"/>
    </collision>
    <inertial>
      <mass value="1e-5"/>
      <inertia ixx="1e-6" ixy="0" ixz="0" iyy="1e-6" iyz="0" izz="1e-6"/>
    </inertial>
  </link>
  <gazebo reference="ground_sonar">
    <material>Gazebo/Gold</material>
  </gazebo>
  <joint name="ground_sonar_base" type="fixed">
    <parent link="box_link"/>
    <child link="ground_sonar"/>
    <origin rpy="0 1.570796 0" xyz="0 0 -0.155"/>
  </joint>
  <!-- ROS Control-->
  <!-- Juntas -->
  <transmission name="tran_joint_1f">
    <type>transmission_interface/SimpleTransmission</type>
    <joint name="joint1_f">
      <hardwareInterface>hardware_interface/EffortJointInterface</hardwareInterface>
    </joint>
    <actuator name="servo11">
      <hardwareInterface>EffortJointInterface</hardwareInterface>
      <mechanicalReduction>1</mechanicalReduction>
    </actuator>
  </transmission>
  <transmission name="tran_joint_2f">
    <type>transmission_interface/SimpleTransmission</type>
    <joint name="joint2_f">
      <hardwareInterface>hardware_interface/EffortJointInterface</hardwareInterface>
    </joint>
    <actuator name="servo13">
      <hardwareInterface>EffortJointInterface</hardwareInterface>
      <mechanicalReduction>1</mechanicalReduction>
    </actuator>
  </transmission>
  <transmission name="tran_joint_1t">
    <type>transmission_interface/SimpleTransmission</type>
    <joint name="joint1_b">
      <hardwareInterface>hardware_interface/EffortJointInterface</hardwareInterface>
    </joint>
    <actuator name="servo22">
      <hardwareInterface>EffortJointInterface</hardwareInterface>
      <mechanicalReduction>1</mechanicalReduction>
    </actuator>
  </transmission>
  <transmission name="tran_joint_2t">
    <type>transmission_interface/SimpleTransmission</type>
    <joint name="joint2_b">
      <hardwareInterface>hardware_interface/EffortJointInterface</hardwareInterface>
    </joint>
    <actuator name="servo24">
      <hardwareInterface>EffortJointInterface</hardwareInterface>
      <mechanicalReduction>1</mechanicalReduction>
    </actuator>
  </transmission>
  <!-- Garras -->
  <transmission name="tran_claw_c1">
    <type>transmission_interface/SimpleTransmission</type>
    <joint name="joint_garra_ap">
      <hardwareInterface>hardware_interface/EffortJointInterface</hardwareInterface>
    </joint>
    <actuator name="servo9">
      <hardwareInterface>EffortJointInterface</hardwareInterface>
      <mechanicalReduction>1</mechanicalReduction>
    </actuator>
  </transmission>
  <transmission name="tran_claw_f1">
    <type>transmission_interface/SimpleTransmission</type>
    <joint name="joint_garra_tracao_f1">
      <hardwareInterface>hardware_interface/EffortJointInterface</hardwareInterface>
    </joint>
    <actuator name="servo15">
      <hardwareInterface>EffortJointInterface</hardwareInterface>
      <mechanicalReduction>1</mechanicalReduction>
    </actuator>
  </transmission>
  <transmission name="tran_claw_f2">
    <type>transmission_interface/SimpleTransmission</type>
    <joint name="joint_garra_tracao_f2">
      <hardwareInterface>hardware_interface/EffortJointInterface</hardwareInterface>
    </joint>
    <actuator name="servo17">
      <hardwareInterface>EffortJointInterface</hardwareInterface>
      <mechanicalReduction>1</mechanicalReduction>
    </actuator>
  </transmission>
  <transmission name="tran_claw_t1">
    <type>transmission_interface/SimpleTransmission</type>
    <joint name="joint_garra_tracao_b1">
      <hardwareInterface>hardware_interface/EffortJointInterface</hardwareInterface>
    </joint>
    <actuator name="servo25">
      <hardwareInterface>EffortJointInterface</hardwareInterface>
      <mechanicalReduction>1</mechanicalReduction>
    </actuator>
  </transmission>
  <transmission name="tran_claw_t2">
    <type>transmission_interface/SimpleTransmission</type>
    <joint name="joint_garra_tracao_b2">
      <hardwareInterface>hardware_interface/EffortJointInterface</hardwareInterface>
    </joint>
    <actuator name="servo27">
      <hardwareInterface>EffortJointInterface</hardwareInterface>
      <mechanicalReduction>1</mechanicalReduction>
    </actuator>
  </transmission>
  <!-- Velocity Controllers -->
  <transmission name="tran_tracao_1c">
    <type>transmission_interface/SimpleTransmission</type>
    <joint name="joint_eixo_tracao_ap">
      <hardwareInterface>hardware_interface/VelocityJointInterface</hardwareInterface>
    </joint>
    <actuator name="servo10">
      <hardwareInterface>VelocityJointInterface</hardwareInterface>
      <mechanicalReduction>1</mechanicalReduction>
    </actuator>
  </transmission>
  <transmission name="tran_tracao_1f">
    <type>transmission_interface/SimpleTransmission</type>
    <joint name="joint_eixo_tracao_f1">
      <hardwareInterface>hardware_interface/VelocityJointInterface</hardwareInterface>
    </joint>
    <actuator name="servo16">
      <hardwareInterface>VelocityJointInterface</hardwareInterface>
      <mechanicalReduction>1</mechanicalReduction>
    </actuator>
  </transmission>
  <transmission name="tran_tracao_2f">
    <type>transmission_interface/SimpleTransmission</type>
    <joint name="joint_eixo_tracao_f2">
      <hardwareInterface>hardware_interface/VelocityJointInterface</hardwareInterface>
    </joint>
    <actuator name="servo18">
      <hardwareInterface>VelocityJointInterface</hardwareInterface>
      <mechanicalReduction>1</mechanicalReduction>
    </actuator>
  </transmission>
  <transmission name="tran_tracao_1t">
    <type>transmission_interface/SimpleTransmission</type>
    <joint name="joint_eixo_tracao_b1">
      <hardwareInterface>hardware_interface/VelocityJointInterface</hardwareInterface>
    </joint>
    <actuator name="servo26">
      <hardwareInterface>VelocityJointInterface</hardwareInterface>
      <mechanicalReduction>1</mechanicalReduction>
    </actuator>
  </transmission>
  <transmission name="tran_tracao_2t">
    <type>transmission_interface/SimpleTransmission</type>
    <joint name="joint_eixo_tracao_b2">
      <hardwareInterface>hardware_interface/VelocityJointInterface</hardwareInterface>
    </joint>
    <actuator name="servo28">
      <hardwareInterface>VelocityJointInterface</hardwareInterface>
      <mechanicalReduction>1</mechanicalReduction>
    </actuator>
  </transmission>
</robot>
