<?xml version="1.0" ?>
<robot name="elir_robot" xmlns:xacro="http://www.ros.org/wiki/xacro">
  <!-- Properties -->
  <!-- Macros -->
  <!-- Gazebo -->
  <!-- ros_control plugin -->
  <xacro:include filename="$(find mybot_description)/urdf/materials.xacro" />
  <xacro:include filename="$(find mybot_description)/urdf/elir.gazebo.xacro" />
  <xacro:property name="M_PI" value="3.141592" />
  <!-- Parametros do box_link-->
  <link name="base_link">
  </link>

  <joint name="base_joint" type="fixed">
    <origin xyz="0.0 0.0 ${0.2357/2}" rpy="0.0 0.0 0.0"/>
    <parent link="base_link"/>
    <child link="box_link"/>
    <axis xyz="0.0 0.0 0.0"/>
    <limit lower="0.0" upper="0.0" effort="0.0" velocity="0.0"/>
  </joint>

  <!-- This link represents the base body of the robot, the central stem and the central's claw base -->
  <link name="box_link">
    <!-- This visual represents the base body-->
    <visual name = 'base_body'>
      <geometry>
        <box size= "0.3219 0.1461 0.2357"/>
      </geometry>
      <material name="grey"/>
    </visual>
    <!-- This visual represents the central stem -->
    <visual name = 'central_stem'>
      <geometry>
        <box size="0.0367 0.0367 0.279"/>
      </geometry>
      <material name="grey"/>
      <!-- <xacro:insert_block name="a.test_central_stem_origin" /> -->
      <origin rpy="0 0 0" xyz="0 0.0303 0.23365"/>
    </visual>
    <!-- This visual represents the claw's base in the central stem -->
    <!-- Need to check mesh design to see if dimensions is the same as the actual dimensions of elir -->
    <visual name = 'central_claw_base'>
      <geometry>
        <mesh filename="package://mybot_description/meshes/dxl_mx106.dae"/>
      </geometry>
      <material name="black"/>
      <origin rpy="0 0 0" xyz="0.0 0.0722 0.3554"/>
    </visual>
    <!-- This collision is for the base_body -->
    <collision name = 'base_body'>
      <geometry>
        <box size="0.3219 0.1461 0.2357"/>
      </geometry>
      <origin rpy="0 0 0" xyz="0.0 0.0 0"/>
    </collision>
    <!-- This collision is for the central_stem -->
    <collision name = 'central_stem'>
      <geometry>
        <box size="0.0367 0.0367 0.279"/>
      </geometry>
      <origin rpy="0 0 0" xyz="0 0.0303 0.23365"/>
    </collision>
    <!-- This collision is for the central_claw_base -->
    <collision name ='central_claw_base'>
      <geometry>
        <mesh filename="package://mybot_description/meshes/dxl_mx106.dae"/>
      </geometry>
      <origin rpy="0 0 0" xyz="0.0 0.0722 0.3554"/>
    </collision>
    <inertial>
      <origin rpy="0 0 0" xyz="-0.00588 0.001 0.0171"/>
      <mass value="4.565"/>
      <inertia ixx="9.8478" ixy="-0.0181" ixz="-0.0877" iyy="15.5246" iyz="-0.5623" izz="9.2774"/>
    </inertial>
  </link>

  <!-- this joint binds the base body (represented by the link box_link) with the central claw unit (represented by the link garra_ap). It can rotate with the z axis fixed, it has an upper limit of 3,14 (180 degrees) and a lower limit of -3,14 (-180 degrees) -->
  <joint name="joint_garra_ap" type="revolute">
    <parent link="box_link"/>
    <child link="garra_ap"/>
    <origin rpy="0 0 ${M_PI}" xyz="0.0 0.0722 0.3554"/>
    <limit effort="1000.0" lower="-3.14" upper="3.14" velocity="0.5"/>
    <axis xyz="0 0 1"/>
  </joint>

  <!-- this link represents the central claw unit -->
  <link name="garra_ap">
    <!-- This visual represents the central claw unit -->
    <!-- Need to check mesh design to see if dimensions is the same as the actual dimensions of elir -->
    <visual name = 'central_claw'>
      <geometry>
        <mesh filename="package://mybot_description/meshes/claw.dae"/>
      </geometry>
      <material name="grey"/>
    </visual>
    <!-- This collision is for the central claw unit -->
    <collision name = 'central_claw'>
      <geometry>
        <mesh filename="package://mybot_description/meshes/claw.dae"/>
      </geometry>
    </collision>
    <inertial>
      <origin rpy="0 0 0" xyz="0.0 0.015953 0.116844"/>
      <mass value="0.22"/>
      <inertia ixx="0.000598" ixy="0.0" ixz="0.0" iyy="0.000866" iyz="0.000169" izz="0.000866"/>
    </inertial>
  </link>

  <!-- this joint binds the central claw unit (represented by the link garra_ap) with the central traction unit (represented by the link eixo_tracao_ap). It can move contunuously with the y axis fixed. It moves forward and backward -->
  <joint name="joint_eixo_tracao_ap" type="continuous">
    <parent link="garra_ap"/>
    <child link="eixo_tracao_ap"/>
    <origin rpy="0 0 0" xyz="0.0 ${0.052+0.006} 0.172"/>
    <axis xyz="0 1 0"/>
    <dynamics damping="0.7" friction="1.0" />
  </joint>

  <!-- this link represents the central traction unit -->
  <link name="eixo_tracao_ap">
    <!-- This visual represents the central traction unit -->
    <!-- Need to check mesh design to see if dimensions is the same as the actual dimensions of elir -->
    <visual name = 'central_traction'>
      <geometry>
         <mesh filename="package://mybot_description/meshes/wheel_elir.STL" scale="0.001 0.001 0.001"/> 
      </geometry>
      <origin rpy="0 0 0" xyz="${-0.030} 0 ${-0.030}"/>
    </visual>
    <!-- This collision is for the central traction unit -->
    <collision name = 'central_traction'>
      <geometry>
         <mesh filename="package://mybot_description/meshes/wheel_elir.STL" scale="0.001 0.001 0.001"/> 
      </geometry>
      <origin rpy="0 0 0" xyz="${-0.030} 0 ${-0.030}"/>
    </collision>
    <inertial>
      <origin rpy="0 0 0" xyz="0.0 0.026065 0.0"/>
      <mass value="0.1"/>
      <inertia ixx="4.94e-05" ixy="0.0" ixz="0.0" iyy="6.11e-05" iyz="0.0" izz="4.94e-05"/>
    </inertial>
  </link>

  <!-- This joint binds the base body (represented by the link box_link) and the front arm unit (represented by the link link1_f). it can rotate with the y axis fixed, it has an upper limit of 0.7 (40 degrees) and a lower limit of -1.74 (-100 degrees) -->
  <joint name="joint1_b" type="revolute">
    <parent link="box_link"/>
    <child link="link1_b"/>
    <!-- <origin rpy=" 0 -0.60 3.141592" xyz="-0.13 0.0 0.079"/> -->
    <origin rpy=" 0 -0.6 ${M_PI}" xyz="-0.13 0.0 0.079"/>
    <limit effort="1000.0" lower="-1.74" upper="0.7" velocity="0.5"/>
    <axis xyz="0 1 0"/>
  </joint>

  <!-- This link represents the front arm unit  -->
  <link name="link1_b">
    <!-- <visual>
      <geometry>
        <box size="0.185 0.102 0.102"/>
      </geometry>
      <material name="grey"/>
      <origin rpy="0 0 0" xyz="0.1985 0.0 0.0"/>
    </visual> -->

    <!-- This visual represents the front arm unit -->
    <visual name = 'back_arm'>
      <geometry>
        <box size="0.19 0.100 0.05"/>
      </geometry>
      <material name="grey"/>
      <origin rpy="0 0 0" xyz="0.20995 0.0 0.0"/>
    </visual>
    <visual name = 'base_left_pallet'>
      <geometry>
        <mesh filename="package://mybot_description/meshes/PIR-M01-003-0_HolderWingWide.STL" scale="0.001 0.001 0.001"/>
      </geometry>
      <material name="black"/>
      <origin rpy="${M_PI/2} 0 0" xyz="0 0.085 ${-0.05/2}"/>
    </visual>
    
    <visual name = 'base_right_pallet'>
      <geometry>
        <mesh filename="package://mybot_description/meshes/PIR-M01-003-0_HolderWingWide.STL" scale="0.001 0.001 0.001"/>
      </geometry>
      <material name="black"/>
      <origin rpy="-${M_PI/2} 0 0" xyz="0 -0.085 ${0.05/2}"/>
    </visual>
        
    <visual name = 'traction_left_pallet'>
      <geometry>
        <mesh filename="package://mybot_description/meshes/PIR-M01-002-0_HolderWing.STL" scale="0.001 0.001 0.001"/>
      </geometry>
      <material name="black"/>
      <origin rpy="${M_PI/2} -${M_PI} 0" xyz="${0.20995*2} 0.06 ${0.05/2}"/>
    </visual>

    <visual name = 'traction_right_pallet'>
      <geometry>
        <mesh filename="package://mybot_description/meshes/PIR-M01-002-0_HolderWing.STL" scale="0.001 0.001 0.001"/>
      </geometry>
      <material name="black"/>
      <origin rpy="-${M_PI/2} -${M_PI} 0" xyz="${0.20995*2} -0.06 -${0.05/2}"/>
    </visual>


    <!-- this collision is for the front arm unit -->
    <collision name = 'back_arm'>
      <geometry>
        <box size="0.19 0.100 0.05"/>
      </geometry>
      <origin rpy="0 0 0" xyz="0.20995 0.0 0.0"/>
    </collision>
    <inertial>
      <origin rpy="0 0 0" xyz="-0.09625 0.08644 0.00657"/>
      <mass value="0.386"/>
      <inertia ixx="0.3971" ixy="0.0" ixz="0.0" iyy="2.2533" iyz="0.0" izz="2.3067"/>
    </inertial>
  </link>

  <!-- This joint binds the base body (represented by the link box_link) and the back arm unit (represented by the link link1_t). it can rotate with the y axis fixed, it has an upper limit of 0.7 (40 degrees) and a lower limit of -1.74 (-100 degrees) -->
  <joint name="joint1_f" type="revolute">
    <parent link="box_link"/>
    <child link="link1_f"/>
    <!-- <origin rpy="0 -0.60 0" xyz="0.13 0.0 0.079"/> -->
    <origin rpy=" 0 -0.6 0" xyz="0.13 0.0 0.079"/>
    <limit effort="1000.0" lower="-1.74" upper="0.7" velocity="0.5"/>
    <axis xyz="0 1 0"/>
  </joint>

  <!-- This link represents the back arm unit  -->
  <link name="link1_f">
    <!-- <visual>
      <geometry>
        <box size="0.185 0.102 0.102"/>
      </geometry>
      <material name="grey"/>
      <origin rpy="0 0 0" xyz="0.1985 0.0 0.0"/>
    </visual> -->

    <!-- This visual represents the back arm unit -->
    <visual name = 'front_arm'>
      <geometry>
        <box size="0.19 0.100 0.05"/>
      </geometry>
      <material name="grey"/>
      <origin rpy="0 0 0" xyz="0.20995 0.0 0.0"/>
    </visual>
    <!-- this collision is for the back arm unit -->
    <visual name = 'base_left_pallet'>
      <geometry>
        <mesh filename="package://mybot_description/meshes/PIR-M01-003-0_HolderWingWide.STL" scale="0.001 0.001 0.001"/>
      </geometry>
      <material name="black"/>
      <origin rpy="${M_PI/2} 0 0" xyz="0 0.085 ${-0.05/2}"/>
    </visual>
    <visual name = 'base_right_pallet'>
      <geometry>
        <mesh filename="package://mybot_description/meshes/PIR-M01-003-0_HolderWingWide.STL" scale="0.001 0.001 0.001"/>
      </geometry>
      <material name="black"/>
      <origin rpy="-${M_PI/2} 0 0" xyz="0 -0.085 ${0.05/2}"/>
    </visual>
        
    <visual name = 'traction_left_pallet'>
      <geometry>
        <mesh filename="package://mybot_description/meshes/PIR-M01-002-0_HolderWing.STL" scale="0.001 0.001 0.001"/>
      </geometry>
      <material name="black"/>
      <origin rpy="${M_PI/2} -${M_PI} 0" xyz="${0.20995*2} 0.06 ${0.05/2}"/>
    </visual>]

    <visual name = 'traction_right_pallet'>
      <geometry>
        <mesh filename="package://mybot_description/meshes/PIR-M01-002-0_HolderWing.STL" scale="0.001 0.001 0.001"/>
      </geometry>
      <material name="black"/>
      <origin rpy="-${M_PI/2} -${M_PI} 0" xyz="${0.20995*2} -0.06 -${0.05/2}"/>
    </visual>
    <collision name = 'front_arm'>
      <geometry>
        <box size="0.19 0.100 0.05"/>
      </geometry>
      <origin rpy="0 0 0" xyz="0.20995 0.0 0.0"/>
    </collision>
    <inertial>
      <origin rpy="0 0 0" xyz="-0.09625 0.08644 0.00657"/>
      <mass value="0.386"/>
      <inertia ixx="0.3971" ixy="0.0" ixz="0.0" iyy="2.2533" iyz="0.0" izz="2.3067"/>
    </inertial>
  </link>

  <!-- This joint binds the front arm unit (represented by the link link1_f) and the front traction body unit (represented by the link tracao_f). It can rotate with the y axis fixed, it has an upper limit of 2.18 (125 degrees) and a lower limit of -1.0 (-57 degrees) -->
  <joint name="joint2_f" type="revolute">
    <parent link="link1_f"/>
    <child link="tracao_f"/>
    <origin rpy="0 0.57 0" xyz="0.39 0.0 0.0"/>
    <limit effort="1000.0" lower="-1.0" upper="2.18" velocity="0.5"/>
    <axis xyz="0 1 0"/>
  </joint>

  <!-- This link represents the front traction body unit that contains front traction body, claw f1 support and claw f2 support -->
  <link name="tracao_f">
    <!-- This visual represents the front traction body -->
    <visual name = 'front_traction_body'>
      <geometry>
        <box size="0.233 0.100 0.100"/>
      </geometry>
      <material name="grey"/>
      <origin rpy="0 0 0" xyz="0.1165 0.0 0.0201"/>
    </visual>
    <!-- This visual represents the front traction claw f2 support -->
    <!-- Need to check mesh design to see if dimensions is the same as the actual dimensions of elir -->
    <visual name = 'front_traction_claw_f1_support'>
      <geometry>
        <box size="0.051 0.045 0.036 "/> 
      </geometry>
      <material name="grey"/>
      <origin rpy="0 0 0" xyz="${0.006 +0.051/2} ${0.05+0.045/2} ${0.05}"/>
    </visual>
    <!-- This visual represents the front traction claw f1 support -->
    <!-- Need to check mesh design to see if dimensions is the same as the actual dimensions of elir -->
    <visual name = 'front_traction_claw_f2_support'>
      <geometry>
        <box size="0.051 0.045 0.036 "/> 
      </geometry>
      <material name="grey"/>
      <origin rpy="0 0 0" xyz="${0.233 -0.006 -0.051/2} ${-0.05-0.045/2} ${0.05}"/>
    </visual>
    <!-- this collision is for the front traction body -->
    <collision name = 'front_traction_body'>
      <geometry>
        <box size="0.233 0.100 0.100"/>
      </geometry>
      <origin rpy="0 0 0" xyz="0.1165 0.0 0.0201"/>
    </collision>
    <!-- this collision is for the front traction claw f2 support -->
    <collision name = 'front_traction_claw_f2_support'>
      <geometry>
        <box size="0.051 0.045 0.036 "/> 
      </geometry>
      <origin rpy="0 0 0" xyz="0.0005 0.075 0.0521"/>
    </collision>
    <!-- this collision is for the front traction claw f1 support -->
    <collision name = 'front_traction_claw_f1_support'>
      <geometry>
        <box size="0.051 0.045 0.036 "/> 
      </geometry>
      <origin rpy="0 0 ${M_PI}" xyz="0.1765 -0.075 0.0521"/>
    </collision>
    <inertial>
      <origin rpy="0 0 0" xyz="0.03499 0.0 0.0"/>
      <mass value="0.792"/>
      <inertia ixx="0.5622" ixy="0.161" ixz="0.0008" iyy="1.0746" iyz="0.0" izz="1.2126"/>
    </inertial>
  </link>

  <!-- This joint binds the back arm unit (represented by the link link1_t) and the back traction body unit (represented by the link tracao_b). It can rotate with the y axis fixed, it has an upper limit of 2.18 (125 degrees) and a lower limit of -1.0 (-57 degrees) -->
  <joint name="joint2_b" type="revolute">
    <parent link="link1_b"/>
    <child link="tracao_b"/>
    <origin rpy="0 0.57 0" xyz="0.39 0.0 0.0"/>
    <limit effort="1000.0" lower="-1.0" upper="2.18" velocity="0.5"/>
    <axis xyz="0 1 0"/>
  </joint>

  <!-- This link represents the back traction body unit that contains back traction body, claw f1 support and claw f2 support -->
  <link name="tracao_b">
    <!-- This visual represents the  back traction body -->
    <visual name = 'back_traction_body'>
      <geometry>
        <box size="0.233 0.100 0.100"/>
      </geometry>
      <material name="grey"/>
      <origin rpy="0 0 0" xyz="0.1165 0.0 0.0201"/>
    </visual>
    <!-- This visual represents the  back traction claw f1 support -->
    <visual name = 'back_traction_claw_f1_support'>
      <geometry>
        <box size="0.051 0.045 0.036 "/> 
      </geometry>
      <material name="grey"/>
      <origin rpy="0 0 0" xyz="${0.006 +0.051/2} ${0.05+0.045/2} ${0.05}"/>
    </visual>
    <!-- This visual represents the  back traction claw f2 support -->
    <visual name = 'back_traction_claw_f2_support'>
      <geometry>
        <box size="0.051 0.045 0.036 "/> 
      </geometry>
      <material name="grey"/>
      <origin rpy="0 0 0" xyz="${0.233 -0.006 -0.051/2} ${-0.05-0.045/2} ${0.05}"/>
    </visual>
    <!-- this collision is for the back traction body -->
    <collision name = 'back_traction_body'>
      <geometry>
        <box size="0.233 0.100 0.100"/>
      </geometry>
      <origin rpy="0 0 0" xyz="0.1165 0.0 0.0201"/>
    </collision>
    <!-- this collision is for the back traction claw f1 support -->
    <collision name = 'back_traction_claw_f1_support'>
      <geometry>
        <box size="0.051 0.045 0.036 "/> 
      </geometry>
      <origin rpy="0 0 0" xyz="0.0005 -0.075 0.0521"/>
    </collision>
    <!-- this collision is for the back traction claw f2 support -->
    <collision name = 'back_traction_claw_f2_support'>
      <geometry>
        <box size="0.051 0.045 0.036 "/> 
      </geometry>
      <origin rpy="0 0 ${M_PI}" xyz="0.1765 0.075 0.0521"/>
    </collision>
    <inertial>
      <origin rpy="0 0 0" xyz="0.03499 0.0 0.0"/>
      <mass value="0.792"/>
      <inertia ixx="0.5622" ixy="0.161" ixz="0.0008" iyy="1.0746" iyz="0.0" izz="1.2126"/>
    </inertial>
  </link>

  <!-- This joint binds the front traction body unit (represented by the link tracao_f) and the front f1 claw unit (represented by the link garra_tracao_f1). It can rotate with the z axis fixed, it has an upper limit of 3.14 (360 degrees) and lower limit of -3.14 (-360 degrees) -->
  <joint name="joint_garra_tracao_f1" type="revolute">
    <parent link="tracao_f"/>
    <child link="garra_tracao_f1"/>
    <origin rpy="0 0 ${M_PI}" xyz="${0.006+0.011} ${0.05+0.028} ${0.05+0.018+0.0045}"/>
    <limit effort="1000.0" lower="-3.14" upper="3.14" velocity="0.5"/>
    <axis xyz="0 0 1"/>
  </joint>

  <!-- this link represents the front f1 claw unit -->
  <link name="garra_tracao_f1">
    <!-- Need to check mesh design to see if dimensions is the same as the actual dimensions of elir -->
    <!-- This visual represents the front f1 claw unit -->
    <visual>
      <geometry>
        <mesh filename="package://mybot_description/meshes/claw.dae"/>
      </geometry>
      <material name="grey"/>
      <origin rpy="0 0 0" xyz="0.0 0.0 0.0"/>
    </visual>
    <!-- this collision is for the front f1 claw unit -->
    <collision>
      <geometry>
        <mesh filename="package://mybot_description/meshes/claw.dae"/>
      </geometry>
      <origin rpy="0 0 0" xyz="0.0 0.0 0.0"/>
    </collision>
    <inertial>
      <origin rpy="0 0 0" xyz="0.0 0.015953 0.116844"/>
      <mass value="0.22"/>
      <inertia ixx="0.000598" ixy="0.0" ixz="0.0" iyy="0.000866" iyz="0.000169" izz="0.000866"/>
    </inertial>
  </link>

  <!-- this joint binds the front f1 claw unit (represented by the link garra_tracao_f1) with the front f1 traction unit (represented by the link eixo_tracao_f1). It can move contunuously with the y axis fixed. It moves forward and backward -->
  <joint name="joint_eixo_tracao_f1" type="continuous">
    <parent link="garra_tracao_f1"/>
    <child link="eixo_tracao_f1"/>
    <origin rpy="0 0 0" xyz="0.0 ${0.052+0.006} 0.172"/>
    <axis xyz="0 1 0"/>
    <dynamics damping="0.7" friction="1.0" />
  </joint>

  <!-- this link represents the front f1 traction unit -->
  <link name="eixo_tracao_f1">
    <!-- This visual represents the front f1 traction unit -->
    <!-- Need to check mesh design to see if dimensions is the same as the actual dimensions of elir -->
    <visual>
      <geometry>
         <mesh filename="package://mybot_description/meshes/wheel_elir.STL" scale="0.001 0.001 0.001"/> 
      </geometry>
      <material name="grey"/>
      <origin rpy="0 0 0" xyz="-0.03 0 ${-0.061/2}"/>
    </visual>
    <!-- This collision is for the front f1 traction unit -->
    <collision>
      <geometry>
         <mesh filename="package://mybot_description/meshes/wheel_elir.STL" scale="0.001 0.001 0.001"/> 
      </geometry>
      <origin rpy="0 0 0" xyz="-0.03 0 -0.03"/>
    </collision>
    <inertial>
      <origin rpy="0 0 0" xyz="0.0 0.026065 0.0"/>
      <mass value="0.1"/>
      <inertia ixx="4.94e-05" ixy="0.0" ixz="0.0" iyy="6.11e-05" iyz="0.0" izz="4.94e-05"/>
    </inertial>
  </link>

  <!-- This joint binds the front traction body unit (represented by the link tracao_f) and the front f2 claw unit (represented by the link garra_tracao_f2). It can rotate with the z axis fixed, it has an upper limit of 3.14 (360 degrees) and lower limit of -3.14 (-360 degrees) -->
  <joint name="joint_garra_tracao_f2" type="revolute">
    <parent link="tracao_f"/>
    <child link="garra_tracao_f2"/>
    <origin rpy="0 0 0" xyz="${0.233 -0.006 -0.011} ${-0.05-0.028} ${0.05+0.018+0.0045}"/>
    <limit effort="1000.0" lower="-3.14" upper="3.14" velocity="0.5"/>
    <axis xyz="0 0 1"/>
  </joint>

  <!-- this link represents the front f2 claw unit -->
  <link name="garra_tracao_f2">
    <!-- Need to check mesh design to see if dimensions is the same as the actual dimensions of elir -->
    <!-- This visual represents the front f2 claw unit -->
    <visual>
      <geometry>
        <mesh filename="package://mybot_description/meshes/claw.dae"/>
      </geometry>
      <material name="grey"/>
      <origin rpy="0 0 0" xyz="0.0 0.0 0.0"/>
    </visual>
    <!-- this collision is for the front f2 claw unit -->
    <collision>
      <geometry>
        <mesh filename="package://mybot_description/meshes/claw.dae"/>
      </geometry>
      <origin rpy="0 0 0" xyz="0.0 0.0 0.0"/>
    </collision>
    <inertial>
      <origin rpy="0 0 0" xyz="0.0 0.015953 0.116844"/>
      <mass value="0.22"/>
      <inertia ixx="0.000598" ixy="0.0" ixz="0.0" iyy="0.000866" iyz="0.000169" izz="0.000866"/>
    </inertial>
  </link>

  <!-- this joint binds the front f2 claw unit (represented by the link garra_tracao_f2) with the front f2 traction unit (represented by the link eixo_tracao_f2). It can move contunuously with the y axis fixed. It moves forward and backward -->
  <joint name="joint_eixo_tracao_f2" type="continuous">
    <parent link="garra_tracao_f2"/>
    <child link="eixo_tracao_f2"/>
    <origin rpy="0 0 0" xyz="0.0 ${0.052+0.006} 0.172"/>
    <axis xyz="0 1 0"/>
    <dynamics damping="0.7" friction="1.0" />
  </joint>

  <!-- this link represents the front f2 traction unit -->
  <link name="eixo_tracao_f2">
    <!-- This visual represents the front f2 traction unit -->
    <!-- Need to check mesh design to see if dimensions is the same as the actual dimensions of elir -->
    <visual>
      <geometry>
         <mesh filename="package://mybot_description/meshes/wheel_elir.STL" scale="0.001 0.001 0.001"/> 
      </geometry>
      <material name="grey"/>
      <origin rpy="0 0 0" xyz="-0.03 0 -0.03"/>
    </visual>
    <!-- This collision is for the front f2 traction unit -->
    <collision>
      <geometry>
         <mesh filename="package://mybot_description/meshes/wheel_elir.STL" scale="0.001 0.001 0.001"/> 
      </geometry>
      <origin rpy="0 0 0" xyz="-0.03 0 -0.03"/>
    </collision>
    <inertial>
      <origin rpy="0 0 0" xyz="0.0 0.026065 0.0"/>
      <mass value="0.1"/>
      <inertia ixx="4.94e-05" ixy="0.0" ixz="0.0" iyy="6.11e-05" iyz="0.0" izz="4.94e-05"/>
    </inertial>
  </link>


  <!-- GARRAS TRACAO TRASEIRA -->
  <!-- T1 -->
  <!-- This joint binds the front traction body unit (represented by the link tracao_f) and the back t1 claw unit (represented by the link garra_tracao_b1). It can rotate with the z axis fixed, it has an upper limit of 3.14 (360 degrees) and lower limit of -3.14 (-360 degrees) -->
  <joint name="joint_garra_tracao_b1" type="revolute">
    <parent link="tracao_b"/>
    <child link="garra_tracao_b1"/>
    <origin rpy="0 0 ${M_PI}" xyz="${0.006+0.011} ${0.05+0.028} ${0.05+0.018+0.0045}"/>
    <limit effort="1000.0" lower="-3.14" upper="3.14" velocity="0.5"/>
    <axis xyz="0 0 1"/>
  </joint>
  <!-- this link represents the back t1 claw unit -->
  <link name="garra_tracao_b1">
    <!-- Need to check mesh design to see if dimensions is the same as the actual dimensions of elir -->
    <!-- This visual represents the back t1 claw unit -->
    <visual>
      <geometry>
        <mesh filename="package://mybot_description/meshes/claw.dae"/>
      </geometry>
      <material name="grey"/>
      <origin rpy="0 0 0" xyz="0.0 0.0 0.0"/>
    </visual>
    <!-- this collision is for the back t1 claw unit -->
    <collision>
      <geometry>
        <mesh filename="package://mybot_description/meshes/claw.dae"/>
      </geometry>
      <origin rpy="0 0 0" xyz="0.0 0.0 0.0"/>
    </collision>
    <inertial>
      <origin rpy="0 0 0" xyz="0.0 0.015953 0.116844"/>
      <mass value="0.22"/>
      <inertia ixx="0.000598" ixy="0.0" ixz="0.0" iyy="0.000866" iyz="0.000169" izz="0.000866"/>
    </inertial>
  </link>

  <!-- Eixo T1 -->
  <!-- this joint binds the back t1 claw unit (represented by the link garra_tracao_b1) with the back t1 traction unit (represented by the link eixo_tracao_b1). It can move contunuously with the y axis fixed. It moves forward and backward -->
  <joint name="joint_eixo_tracao_b1" type="continuous">
    <parent link="garra_tracao_b1"/>
    <child link="eixo_tracao_b1"/>
    <origin rpy="0 0 0" xyz="0.0 ${0.052+0.006} 0.172"/>
    <axis xyz="0 1 0"/>
    <dynamics damping="0.7" friction="1.0" />
  </joint>
  <!-- this link represents the back t1 traction unit -->
  <link name="eixo_tracao_b1">
    <!-- This visual represents the back t1 traction unit -->
    <!-- Need to check mesh design to see if dimensions is the same as the actual dimensions of elir -->
    <visual>
      <geometry>
         <mesh filename="package://mybot_description/meshes/wheel_elir.STL" scale="0.001 0.001 0.001"/> 
      </geometry>
      <material name="grey"/>
      <origin rpy="0 0 0" xyz="-0.03 0 -0.03"/>
    </visual>
    <!-- This collision is for the back t1 traction unit -->
    <collision>
      <geometry>
         <mesh filename="package://mybot_description/meshes/wheel_elir.STL" scale="0.001 0.001 0.001"/> 
      </geometry>
      <origin rpy="0 0 0" xyz="-0.03 0 -0.03"/>
    </collision>
    <inertial>
      <origin rpy="0 0 0" xyz="0.0 0.026065 0.0"/>
      <mass value="0.1"/>
      <inertia ixx="4.94e-05" ixy="0.0" ixz="0.0" iyy="6.11e-05" iyz="0.0" izz="4.94e-05"/>
    </inertial>
  </link>

  <!-- T2 -->
  <!-- This joint binds the front traction body unit (represented by the link tracao_f) and the back t2 claw unit (represented by the link garra_tracao_b2). It can rotate with the z axis fixed, it has an upper limit of 3.14 (360 degrees) and lower limit of -3.14 (-360 degrees) -->
  <joint name="joint_garra_tracao_b2" type="revolute">
    <parent link="tracao_b"/>
    <child link="garra_tracao_b2"/>
    <origin rpy="0 0 0" xyz="${0.233 -0.006 -0.011} ${-0.05-0.028} ${0.05+0.018+0.0045}"/>
    <limit effort="1000.0" lower="-3.14" upper="3.14" velocity="0.5"/>
    <axis xyz="0 0 1"/>
  </joint>
  <!-- this link represents the back t2 claw unit -->
  <link name="garra_tracao_b2">
    <!-- Need to check mesh design to see if dimensions is the same as the actual dimensions of elir -->
    <!-- This visual represents the back t2 claw unit -->
    <visual>
      <geometry>
        <mesh filename="package://mybot_description/meshes/claw.dae"/>
      </geometry>
      <material name="grey"/>
      <origin rpy="0 0 0" xyz="0.0 0.0 0.0"/>
    </visual>
    <!-- this collision is for the back t2 claw unit -->
    <collision>
      <geometry>
        <mesh filename="package://mybot_description/meshes/claw.dae"/>
      </geometry>
      <origin rpy="0 0 0" xyz="0.0 0.0 0.0"/>
    </collision>
    <inertial>
      <origin rpy="0 0 0" xyz="0.0 0.015953 0.116844"/>
      <mass value="0.22"/>
      <inertia ixx="0.000598" ixy="0.0" ixz="0.0" iyy="0.000866" iyz="0.000169" izz="0.000866"/>
    </inertial>
  </link>

  <!-- Eixo F2 -->
  <!-- this joint binds the back t2 claw unit (represented by the link garra_tracao_b2) with the back t2 traction unit (represented by the link eixo_tracao_b2). It can move contunuously with the y axis fixed. It moves forward and backward -->
  <joint name="joint_eixo_tracao_b2" type="continuous">
    <parent link="garra_tracao_b2"/>
    <child link="eixo_tracao_b2"/>
    <origin rpy="0 0 0" xyz="0.0 ${0.052+0.006} 0.172"/>
    <axis xyz="0 1 0"/>
    <dynamics damping="0.7" friction="1.0" />
  </joint>
  <!-- this link represents the back t2 traction unit -->
  <link name="eixo_tracao_b2">
    <!-- This visual represents the back t2 traction unit -->
    <!-- Need to check mesh design to see if dimensions is the same as the actual dimensions of elir -->
    <visual>
      <geometry>
         <mesh filename="package://mybot_description/meshes/wheel_elir.STL" scale="0.001 0.001 0.001"/> 
      </geometry>
      <material name="grey"/>
      <origin rpy="0 0 0" xyz="-0.03 0 -0.03"/>
    </visual>
    <!-- This collision is for the back t2 traction unit -->
    <collision>
      <geometry>
         <mesh filename="package://mybot_description/meshes/wheel_elir.STL" scale="0.001 0.001 0.001"/> 
      </geometry>
      <origin rpy="0 0 0" xyz="-0.03 0 -0.03"/>
    </collision>
    <inertial>
      <origin rpy="0 0 0" xyz="0.0 0.026065 0.0"/>
      <mass value="0.1"/>
      <inertia ixx="4.94e-05" ixy="0.0" ixz="0.0" iyy="6.11e-05" iyz="0.0" izz="4.94e-05"/>
    </inertial>
  </link>
  <link name="zed_left_camera">
        <visual>
            <origin xyz="0 0 0" rpy="0 1.57 0"/>
            <geometry>
                <cylinder radius="0.007" length=".031"/>
            </geometry>
            <material name="dark_grey">
                <color rgba="0.1 0.1 0.1 1"/>
            </material>
        </visual>
    </link>
    <link name="zed_center">
        <visual>
            <origin xyz="0 0 0" rpy="0 0 0"/>
            <geometry>
                <mesh filename="package://mybot_description/meshes/ZED.stl" />
            </geometry>
            <material name="light_grey">
                <color rgba="0.8 0.8 0.8 0.8"/>
            </material>
        </visual>
    </link>
  <link name="zed_right_camera">
        <visual>
            <origin xyz="0 0 0" rpy="0 1.57 0"/>
            <geometry>
                <cylinder radius="0.007" length=".031"/>
            </geometry>
            <material name="dark_grey">
                <color rgba="0.1 0.1 0.1 1"/>
            </material>
        </visual>
    </link>
    <link name="zed_depth_camera" />
    <joint name="zed_left_camera_joint" type="fixed">
        <parent link="zed_center"/>
        <child link="zed_left_camera"/>
        <origin xyz="0 0.06 0" rpy="0 0 0" />
    </joint>
    <joint name="zed_depth_camera_joint" type="fixed">
        <parent link="zed_left_camera"/>
        <child link="zed_depth_camera"/>
        <origin xyz="0 0 0" rpy="-1.5707963267948966 0 -1.5707963267948966" />
    </joint>

    <joint name="zed_right_camera_joint" type="fixed">
        <parent link="zed_center"/>
        <child link="zed_right_camera"/>
        <origin xyz="0 -0.06 0" rpy="0 0 0" />
    </joint>

    <link name="flir_camera">
        <visual>
            <origin xyz="0 0 0" rpy="0 ${M_PI/2} 0"/>
            <geometry>
                <mesh filename="package://mybot_description/meshes/LeptonBreakoutBoardWithLepton3.stl" scale="0.001 0.001 0.001"/>
            </geometry>
            <material name="light_grey">
                <color rgba="0.8 0.8 0.8 0.8"/>
            </material>
        </visual>
    </link>
    



  <joint name="zed_camera_joint" type="fixed">
    <parent link="box_link"/>
    <child link="zed_center"/>
    <origin rpy="0 0 0" xyz="0.17 0.0 -0.1"/>
  </joint>

  <joint name="flir_camera_joint" type="fixed">
    <parent link="box_link"/>
    <child link="flir_camera"/>
    <origin rpy="0 0 0" xyz="0.17 0.0 -0.05"/>
  </joint>

  <!-- Sonares -->

<link name="ground_sonar" >
		<visual>
			<geometry>
      <mesh filename="package://mybot_description/meshes/groundsonar.dae"/>
			</geometry>
      <origin rpy="0 ${-M_PI/2} 0" />
    </visual>
    
    <collision>
      <geometry>
        <mesh filename="package://mybot_description/meshes/groundsonar.dae"/>
      </geometry>
      <origin rpy="0 ${-M_PI/2} 0" />
    </collision>

    <inertial>
      <mass value="1e-5"/>
      <inertia ixx="1e-6" ixy="0" ixz="0" iyy="1e-6" iyz="0" izz="1e-6"/>
    </inertial>
	</link>

  <gazebo reference="ground_sonar">
    <material>Gazebo/Gold</material>
  </gazebo>


	<joint name="ground_sonar_base" type="fixed">
		<parent link="box_link" />
		<child link="ground_sonar" />
		<origin xyz="0 0 -0.155" rpy="0 ${M_PI/2} 0" />
	</joint>


 
  <!-- ROS Control-->
  <!-- Juntas -->
  <transmission name="tran_joint_1f">
    <type>transmission_interface/SimpleTransmission</type>
    <joint name="joint1_f">
      <hardwareInterface>hardware_interface/EffortJointInterface</hardwareInterface>
    </joint>
    <actuator name="servo11">
      <hardwareInterface>EffortJointInterface</hardwareInterface>
      <mechanicalReduction>1</mechanicalReduction>
    </actuator>
  </transmission>
  <transmission name="tran_joint_2f">
    <type>transmission_interface/SimpleTransmission</type>
    <joint name="joint2_f">
      <hardwareInterface>hardware_interface/EffortJointInterface</hardwareInterface>
    </joint>
    <actuator name="servo13">
      <hardwareInterface>EffortJointInterface</hardwareInterface>
      <mechanicalReduction>1</mechanicalReduction>
    </actuator>
  </transmission>
  <transmission name="tran_joint_1t">
    <type>transmission_interface/SimpleTransmission</type>
    <joint name="joint1_b">
      <hardwareInterface>hardware_interface/EffortJointInterface</hardwareInterface>
    </joint>
    <actuator name="servo22">
      <hardwareInterface>EffortJointInterface</hardwareInterface>
      <mechanicalReduction>1</mechanicalReduction>
    </actuator>
  </transmission>
  <transmission name="tran_joint_2t">
    <type>transmission_interface/SimpleTransmission</type>
    <joint name="joint2_b">
      <hardwareInterface>hardware_interface/EffortJointInterface</hardwareInterface>
    </joint>
    <actuator name="servo24">
      <hardwareInterface>EffortJointInterface</hardwareInterface>
      <mechanicalReduction>1</mechanicalReduction>
    </actuator>
  </transmission>
  <!-- Garras -->
  <transmission name="tran_claw_c1">
    <type>transmission_interface/SimpleTransmission</type>
    <joint name="joint_garra_ap">
      <hardwareInterface>hardware_interface/EffortJointInterface</hardwareInterface>
    </joint>
    <actuator name="servo9">
      <hardwareInterface>EffortJointInterface</hardwareInterface>
      <mechanicalReduction>1</mechanicalReduction>
    </actuator>
  </transmission>
  <transmission name="tran_claw_f1">
    <type>transmission_interface/SimpleTransmission</type>
    <joint name="joint_garra_tracao_f1">
      <hardwareInterface>hardware_interface/EffortJointInterface</hardwareInterface>
    </joint>
    <actuator name="servo15">
      <hardwareInterface>EffortJointInterface</hardwareInterface>
      <mechanicalReduction>1</mechanicalReduction>
    </actuator>
  </transmission>
  <transmission name="tran_claw_f2">
    <type>transmission_interface/SimpleTransmission</type>
    <joint name="joint_garra_tracao_f2">
      <hardwareInterface>hardware_interface/EffortJointInterface</hardwareInterface>
    </joint>
    <actuator name="servo17">
      <hardwareInterface>EffortJointInterface</hardwareInterface>
      <mechanicalReduction>1</mechanicalReduction>
    </actuator>
  </transmission>
  <transmission name="tran_claw_t1">
    <type>transmission_interface/SimpleTransmission</type>
    <joint name="joint_garra_tracao_b1">
      <hardwareInterface>hardware_interface/EffortJointInterface</hardwareInterface>
    </joint>
    <actuator name="servo25">
      <hardwareInterface>EffortJointInterface</hardwareInterface>
      <mechanicalReduction>1</mechanicalReduction>
    </actuator>
  </transmission>
  <transmission name="tran_claw_t2">
    <type>transmission_interface/SimpleTransmission</type>
    <joint name="joint_garra_tracao_b2">
      <hardwareInterface>hardware_interface/EffortJointInterface</hardwareInterface>
    </joint>
    <actuator name="servo27">
      <hardwareInterface>EffortJointInterface</hardwareInterface>
      <mechanicalReduction>1</mechanicalReduction>
    </actuator>
  </transmission>
  <!-- Velocity Controllers -->
  <transmission name="tran_tracao_1c">
    <type>transmission_interface/SimpleTransmission</type>
    <joint name="joint_eixo_tracao_ap">
      <hardwareInterface>hardware_interface/VelocityJointInterface</hardwareInterface>
    </joint>
    <actuator name="servo10">
      <hardwareInterface>VelocityJointInterface</hardwareInterface>
      <mechanicalReduction>1</mechanicalReduction>
    </actuator>
  </transmission>
  <transmission name="tran_tracao_1f">
    <type>transmission_interface/SimpleTransmission</type>
    <joint name="joint_eixo_tracao_f1">
      <hardwareInterface>hardware_interface/VelocityJointInterface</hardwareInterface>
    </joint>
    <actuator name="servo16">
      <hardwareInterface>VelocityJointInterface</hardwareInterface>
      <mechanicalReduction>1</mechanicalReduction>
    </actuator>
  </transmission>
  <transmission name="tran_tracao_2f">
    <type>transmission_interface/SimpleTransmission</type>
    <joint name="joint_eixo_tracao_f2">
      <hardwareInterface>hardware_interface/VelocityJointInterface</hardwareInterface>
    </joint>
    <actuator name="servo18">
      <hardwareInterface>VelocityJointInterface</hardwareInterface>
      <mechanicalReduction>1</mechanicalReduction>
    </actuator>
  </transmission>
  <transmission name="tran_tracao_1t">
    <type>transmission_interface/SimpleTransmission</type>
    <joint name="joint_eixo_tracao_b1">
      <hardwareInterface>hardware_interface/VelocityJointInterface</hardwareInterface>
    </joint>
    <actuator name="servo26">
      <hardwareInterface>VelocityJointInterface</hardwareInterface>
      <mechanicalReduction>1</mechanicalReduction>
    </actuator>
  </transmission>
  <transmission name="tran_tracao_2t">
    <type>transmission_interface/SimpleTransmission</type>
    <joint name="joint_eixo_tracao_b2">
      <hardwareInterface>hardware_interface/VelocityJointInterface</hardwareInterface>
    </joint>
    <actuator name="servo28">
      <hardwareInterface>VelocityJointInterface</hardwareInterface>
      <mechanicalReduction>1</mechanicalReduction>
    </actuator>
  </transmission>
</robot>
