<?xml version="1.0" ?>
<!-- =================================================================================== -->
<!-- |    This document was autogenerated by xacro from robot.xacro                    | -->
<!-- |    EDITING THIS FILE BY HAND IS NOT RECOMMENDED                                 | -->
<!-- =================================================================================== -->
<robot name="robo_cemig" xmlns:xacro="http://www.ros.org/wiki/xacro">
  <!-- Properties -->
  <!-- Macros -->
  <!-- Gazebo -->
  <!-- ros_control plugin -->
  <xacro:include filename="$(find mybot_description)/urdf/materials.xacro" />
  <xacro:include filename="$(find mybot_description)/urdf/piro.gazebo" />
  <!-- BASE LINK-->
  <!-- Dimensoes da unidade de apoio -->
  <!-- Dimensoes da caixa eletronica -->
  <!--
	<xacro:property name="l_eletr_ap" value="0.240" />
	<xacro:property name="h_eletr_ap" value="0.120" />
	<xacro:property name="w_eletr_ap" value="0.120" />
-->
  <!-- Suporte da garra da unidade de apoio -->
  <!-- Dimensoes do sup_apoio -->
  <!-- Posicoes da base do sup_apoio para o centro do base link -->
  <!-- Parametros do base_link-->
  <link name="base_link">
    <!-- This visual represents the base body of the piro in which the arms will be coupled -->
    <visual name = 'base_body'>
      <geometry>
        <box size="0.3219 0.1461 0.2357"/>
      </geometry>
      <material name="grey"/>
    </visual>
    <!-- This visual represents the central stem -->
    <visual name = 'central_stem'>
      <geometry>
        <box size="0.0367 0.0367 0.279"/>
      </geometry>
      <material name="grey"/>
      <origin rpy="0 0 0" xyz="0 0.0303 0.23365"/>
    </visual>
    <!--
		<visual>
			<geometry>
				<box size="${l_eletr_ap} ${w_eletr_ap} ${h_eletr_ap}"/>
			</geometry>
			<xacro:cor />
			<origin xyz="0 0 ${-h_ap/2 + -h_eletr_ap/2}" rpy="0 0 0" />
		</visual>
    -->
    <!-- This visual represents the claw's base in the central stem -->
    <visual name = 'central_claw_base'>
      <geometry>
        <mesh filename="package://mybot_description/meshes/dxl_mx106.dae"/>
      </geometry>
      <material name="grey"/>
      <origin rpy="0 0 0" xyz="0.0 0.0722 0.3554"/>
    </visual>
    <collision>
      <geometry>
        <box size="0.3 0.1434 0.232"/>
      </geometry>
      <origin rpy="0 0 0" xyz="0.0 0.0 0"/>
    </collision>
    <collision>
      <geometry>
        <box size="0.03 0.03 0.232"/>
      </geometry>
      <origin rpy="0 0.0 0" xyz="0.0 0.03 0.25"/>
    </collision>

    <inertial>
      <origin rpy="0 0 0" xyz="-0.00588 0.001 0.0171"/>
      <mass value="4.565"/>
      <inertia ixx="9.8478" ixy="-0.0181" ixz="-0.0877" iyy="15.5246" iyz="-0.5623" izz="9.2774"/>
    </inertial>
  </link>

  <joint name="joint_garra_ap" type="revolute">
    <parent link="base_link"/>
    <child link="garra_ap"/>
    <origin rpy="0 0 3.141592" xyz="0.0 0.0722 0.3554"/>
    <limit effort="1000.0" lower="-3.14" upper="3.14" velocity="0.5"/>
    <axis xyz="0 0 1"/>
  </joint>
  <!-- GARRA DE APOIO -->
  <!-- Garra da unidade de apoio -->
  <!-- -->
  <!-- dimensao da base do motor para seu centro-->
  <!-- Posicao da junta da garra_apoio -->
  <!-- Posicao do eixo de tracao da garra_apoio -->
  <!-- Angulos da garra de apoio -->
  <!-- Parametros da garra-->
  <link name="garra_ap">
    <visual>
      <geometry>
        <mesh filename="package://mybot_description/meshes/claw.dae"/>
      </geometry>
      <material name="grey"/>
    </visual>
    <collision>
      <geometry>
        <box size="0.048 0.064 0.1851"/>
      </geometry>
      <origin rpy="0 0 0" xyz="0.0 0.017 0.09255"/>
    </collision>
    <inertial>
      <origin rpy="0 0 0" xyz="0.0 0.015953 0.116844"/>
      <mass value="0.22"/>
      <inertia ixx="0.000598" ixy="0.0" ixz="0.0" iyy="0.000866" iyz="0.000169" izz="0.000866"/>
    </inertial>
  </link>
  <!-- Eixo AP -->
  <!-- Parametros do eixo-->
  <link name="eixo_tracao_ap">
    <visual>
      <geometry>
        <mesh filename="package://mybot_description/meshes/shaft_simple.dae"/>
      </geometry>
    </visual>
    <collision>
      <geometry>
        <mesh filename="package://mybot_description/meshes/shaft_simple.dae"/>
      </geometry>
    </collision>
    <inertial>
      <origin rpy="0 0 0" xyz="0.0 0.026065 0.0"/>
      <mass value="0.1"/>
      <inertia ixx="4.94e-05" ixy="0.0" ixz="0.0" iyy="6.11e-05" iyz="0.0" izz="4.94e-05"/>
    </inertial>
  </link>
  <joint name="joint_eixo_tracao_ap" type="continuous">
    <parent link="garra_ap"/>
    <child link="eixo_tracao_ap"/>
    <origin rpy="0 0 0" xyz="0.0 0.049 0.1345"/>
    <axis xyz="0 1 0"/>
    <dynamics damping="0.7" friction="1.0" />
  </joint>
  <!-- JUNTA 1 -->
  <!-- Dimensoes do link1 collision -->
  <!-- Dimensoes do link1  -->
  <!-- Link1 collision offset-->
  <!-- Posicao do link1 -->
  <!-- Posicao da junta1 -->
  <!-- Angulo da junta1 -->
  <!-- Parametros do link1-->
  <!-- Link F1 -->
  <link name="link1_f">
    <visual>
      <geometry>
        <box size="0.185 0.102 0.102"/>
      </geometry>
      <material name="grey"/>


      <origin rpy="0 0 0" xyz="0.1985 0.0 0.0"/>
    </visual>
    <visual>
      <geometry>
        <box size="0.405 0.102 0.03"/>
      </geometry>
      <material name="grey"/>


      <origin rpy="0 0 0" xyz="0.1885 0.0 0.0"/>
    </visual>
    <collision>
      <geometry>
        <box size="0.185 0.102 0.102"/>
      </geometry>
      <origin rpy="0 0 0" xyz="0.1885 0.0 0.0"/>
    </collision>
    <inertial>
      <origin rpy="0 0 0" xyz="-0.09625 0.08644 0.00657"/>
      <mass value="0.386"/>
      <inertia ixx="0.3971" ixy="0.0" ixz="0.0" iyy="2.2533" iyz="0.0" izz="2.3067"/>
    </inertial>
  </link>
  <joint name="joint1_f" type="revolute">
    <parent link="base_link"/>
    <child link="link1_f"/>
    <origin rpy=" 0 0 3.141592" xyz="-0.13 0.0 0.079"/>
    <limit effort="1000.0" lower="-1.74" upper="0.7" velocity="0.5"/>
    <axis xyz="0 1 0"/>
  </joint>
  <!-- Link T1 -->
  <link name="link1_t">
    <visual>
      <geometry>
        <box size="0.185 0.102 0.102"/>
      </geometry>
      <material name="grey"/>


      <origin rpy="0 0 0" xyz="0.1985 0.0 0.0"/>
    </visual>
    <visual>
      <geometry>
        <box size="0.405 0.102 0.03"/>
      </geometry>
      <material name="grey"/>


      <origin rpy="0 0 0" xyz="0.1885 0.0 0.0"/>
    </visual>
    <collision>
      <geometry>
        <box size="0.185 0.102 0.102"/>
      </geometry>
      <origin rpy="0 0 0" xyz="0.1885 0.0 0.0"/>
    </collision>
    <inertial>
      <origin rpy="0 0 0" xyz="-0.09625 0.08644 0.00657"/>
      <mass value="0.386"/>
      <inertia ixx="0.3971" ixy="0.0" ixz="0.0" iyy="2.2533" iyz="0.0" izz="2.3067"/>
    </inertial>
  </link>
  <joint name="joint1_t" type="revolute">
    <parent link="base_link"/>
    <child link="link1_t"/>
    <origin rpy="0 0 0" xyz="0.13 0.0 0.079"/>
    <limit effort="1000.0" lower="-1.74" upper="0.7" velocity="0.5"/>
    <axis xyz="0 1 0"/>
  </joint>
  <!-- TRACAO -->
  <!-- Dimensoes da tracao -->
  <!-- Posicao da tracao em relacao a junta1-->
  <!-- Dimensao dos servos -->
  <!-- Posicao dos servos das garras em relacao ao centro da tracao-->
  <!--
	<xacro:property name="x_servo_garra_1" value="-0.007" />
	<xacro:property name="y_servo_garra_1" value="0.0750" />
	<xacro:property name="z_servo_garra_1" value="0.0521" />
-->
  <!-- Posicao dos servos das garras em relacao ao centro da tracao-->
  <!-- Posicao da junta2 -->
  <!-- Angulo da junta2 -->
  <!-- Parametros da tracao-->
  <!-- TRACAO F -->
  <link name="tracao_f">
    <visual>
      <geometry>
        <box size="0.233 0.102 0.102"/>
      </geometry>
      <material name="grey"/>


      <origin rpy="0 0 0" xyz="0.0885 0.0 0.0201"/>
    </visual>
    <visual>
      <geometry>
        <mesh filename="package://mybot_description/meshes/dxl_mx106.dae"/>
      </geometry>
      <material name="grey"/>


      <origin rpy="0 0 0" xyz="0.0005 0.075 0.0521"/>
    </visual>
    <visual>
      <geometry>
        <mesh filename="package://mybot_description/meshes/dxl_mx106.dae"/>
      </geometry>
      <material name="grey"/>


      <origin rpy="0 0 3.141592" xyz="0.1765 -0.075 0.0521"/>
    </visual>
    <collision>
      <geometry>
        <box size="0.233 0.198 0.102"/>
      </geometry>
      <origin rpy="0 0 0" xyz="0.0885 0.0 0.0201"/>
    </collision>
    <inertial>
      <origin rpy="0 0 0" xyz="0.03499 0.0 0.0"/>
      <mass value="0.792"/>
      <inertia ixx="0.5622" ixy="0.161" ixz="0.0008" iyy="1.0746" iyz="0.0" izz="1.2126"/>
    </inertial>
  </link>
  <joint name="joint2_f" type="revolute">
    <parent link="link1_f"/>
    <child link="tracao_f"/>
    <origin rpy="0 0 0" xyz="0.39 0.0 0.0"/>
    <limit effort="1000.0" lower="-1.0" upper="2.18" velocity="0.5"/>
    <axis xyz="0 1 0"/>
  </joint>
  <!-- TRACAO T -->
  <link name="tracao_t">
    <visual>
      <geometry>
        <box size="0.233 0.102 0.102"/>
      </geometry>
      <material name="grey"/>
      <origin rpy="0 0 0" xyz="0.0885 0.0 0.0201"/>
    </visual>
    <visual>
      <geometry>
        <mesh filename="package://mybot_description/meshes/dxl_mx106.dae"/>
      </geometry>
      <material name="grey"/>
      <origin rpy="0 0 0" xyz="0.0005 -0.075 0.0521"/>
    </visual>
    <visual>
      <geometry>
        <mesh filename="package://mybot_description/meshes/dxl_mx106.dae"/>
      </geometry>
      <material name="grey"/>
      <origin rpy="0 0 3.141592" xyz="0.1765 0.075 0.0521"/>
    </visual>
    <collision>
      <geometry>
        <box size="0.233 0.198 0.102"/>
      </geometry>
      <origin rpy="0 0 0" xyz="0.0885 0.0 0.0201"/>
    </collision>
    <inertial>
      <origin rpy="0 0 0" xyz="0.03499 0.0 0.0"/>
      <mass value="0.792"/>
      <inertia ixx="0.5622" ixy="0.161" ixz="0.0008" iyy="1.0746" iyz="0.0" izz="1.2126"/>
    </inertial>
  </link>
  <joint name="joint2_t" type="revolute">
    <parent link="link1_t"/>
    <child link="tracao_t"/>
    <origin rpy="0 0 0" xyz="0.39 0.0 0.0"/>
    <limit effort="1000.0" lower="-1.0" upper="2.18" velocity="0.5"/>
    <axis xyz="0 1 0"/>
  </joint>
  <!-- GARRAS DE TRACAO -->
  <!-- Posicoes das garras de tracao-->
  <!-- Angulos da garra de tracao -->
  <!-- GARRAS TRACAO DIANTEIRA -->
  <!-- F1 -->
  <link name="garra_tracao_f1">
    <visual>
      <geometry>
        <mesh filename="package://mybot_description/meshes/claw.dae"/>
      </geometry>
      <material name="grey"/>
      <origin rpy="0 0 0" xyz="0.0 0.012 0.0"/>

    </visual>
    <collision>
      <geometry>
        <box size="0.048 0.064 0.1851"/>
      </geometry>
      <origin rpy="0 0 0" xyz="0.0 0.017 0.09255"/>
    </collision>
    <inertial>
      <origin rpy="0 0 0" xyz="0.0 0.015953 0.116844"/>
      <mass value="0.22"/>
      <inertia ixx="0.000598" ixy="0.0" ixz="0.0" iyy="0.000866" iyz="0.000169" izz="0.000866"/>
    </inertial>
  </link>
  <joint name="joint_garra_tracao_f1" type="revolute">
    <parent link="tracao_f"/>
    <child link="garra_tracao_f1"/>
    <origin rpy="0 0 3.141592" xyz="0.0005 0.075 0.06985"/>
    <limit effort="1000.0" lower="-3.14" upper="3.14" velocity="0.5"/>
    <axis xyz="0 0 1"/>
  </joint>
  <!-- Eixo F1 -->
  <link name="eixo_tracao_f1">
    <visual>
      <geometry>
        <mesh filename="package://mybot_description/meshes/shaft_simple.dae"/>
      </geometry>
      <material name="grey"/>
      <!-- <origin rpy="0 0 0" xyz="0.0 0.012 0.025"/> -->

    </visual>
    <collision>
      <geometry>
        <mesh filename="package://mybot_description/meshes/shaft_simple.dae"/>
      </geometry>
    </collision>
    <inertial>
      <origin rpy="0 0 0" xyz="0.0 0.026065 0.0"/>
      <mass value="0.1"/>
      <inertia ixx="4.94e-05" ixy="0.0" ixz="0.0" iyy="6.11e-05" iyz="0.0" izz="4.94e-05"/>
    </inertial>
  </link>
  <joint name="joint_eixo_tracao_f1" type="continuous">
    <parent link="garra_tracao_f1"/>
    <child link="eixo_tracao_f1"/>
    <origin rpy="0 0 0" xyz="0.0 0.049 0.145"/>
    <axis xyz="0 1 0"/>
    <dynamics damping="0.7" friction="1.0" />
  </joint>
  <!-- F2 -->
  <link name="garra_tracao_f2">
    <visual>
      <geometry>
        <mesh filename="package://mybot_description/meshes/claw.dae"/>
      </geometry>
      <material name="grey"/>
      <origin rpy="0 0 0" xyz="0.0 0.012 0.0"/>

    </visual>
    <collision>
      <geometry>
        <box size="0.048 0.064 0.1851"/>
      </geometry>
      <origin rpy="0 0 0" xyz="0.0 0.017 0.09255"/>
    </collision>
    <inertial>
      <origin rpy="0 0 0" xyz="0.0 0.015953 0.116844"/>
      <mass value="0.22"/>
      <inertia ixx="0.000598" ixy="0.0" ixz="0.0" iyy="0.000866" iyz="0.000169" izz="0.000866"/>
    </inertial>
  </link>
  <joint name="joint_garra_tracao_f2" type="revolute">
    <parent link="tracao_f"/>
    <child link="garra_tracao_f2"/>
    <origin rpy="0 0 0" xyz="0.1765 -0.075 0.06985"/>
    <limit effort="1000.0" lower="-3.14" upper="3.14" velocity="0.5"/>
    <axis xyz="0 0 1"/>
  </joint>
   --&gt;
  <!-- Eixo F2 -->
  <link name="eixo_tracao_f2">
    <visual>
      <geometry>
        <mesh filename="package://mybot_description/meshes/shaft_simple.dae"/>
      </geometry>
      <material name="grey"/>
      <!-- <origin rpy="0 0 0" xyz="0.0 0.012 0.025"/> -->

    </visual>
    <collision>
      <geometry>
        <mesh filename="package://mybot_description/meshes/shaft_simple.dae"/>
      </geometry>
    </collision>
    <inertial>
      <origin rpy="0 0 0" xyz="0.0 0.026065 0.0"/>
      <mass value="0.1"/>
      <inertia ixx="4.94e-05" ixy="0.0" ixz="0.0" iyy="6.11e-05" iyz="0.0" izz="4.94e-05"/>
    </inertial>
  </link>
  <joint name="joint_eixo_tracao_f2" type="continuous">
    <parent link="garra_tracao_f2"/>
    <child link="eixo_tracao_f2"/>
    <origin rpy="0 0 0" xyz="0.0 0.049 0.145"/>
    <axis xyz="0 1 0"/>
    <dynamics damping="0.7" friction="1.0" />
  </joint>

  <!-- GARRAS TRACAO TRASEIRA -->
  <!-- T1 -->
  <link name="garra_tracao_t1">
    <visual>
      <geometry>
        <mesh filename="package://mybot_description/meshes/claw.dae"/>
      </geometry>
      <material name="grey"/>
      <origin rpy="0 0 0" xyz="0.0 0.012 0.0"/>
    </visual>
    <collision>
      <geometry>
        <box size="0.048 0.064 0.1851"/>
      </geometry>
      <origin rpy="0 0 0" xyz="0.0 0.017 0.09255"/>
    </collision>
    <inertial>
      <origin rpy="0 0 0" xyz="0.0 0.015953 0.116844"/>
      <mass value="0.22"/>
      <inertia ixx="0.000598" ixy="0.0" ixz="0.0" iyy="0.000866" iyz="0.000169" izz="0.000866"/>
    </inertial>
  </link>
  <joint name="joint_garra_tracao_t1" type="revolute">
    <parent link="tracao_t"/>
    <child link="garra_tracao_t1"/>
    <origin rpy="0 0 0" xyz="0.0005 -0.075 0.06985"/>
    <limit effort="1000.0" lower="-3.14" upper="3.14" velocity="0.5"/>
    <axis xyz="0 0 1"/>
  </joint>
   --&gt;
  <!-- Eixo T1 -->
  <link name="eixo_tracao_t1">
    <visual>
      <geometry>
        <mesh filename="package://mybot_description/meshes/shaft_simple.dae"/>
      </geometry>
      <material name="grey"/>
      <!-- <origin rpy="0 0 0" xyz="0.0 0.012 0.025"/> -->
    </visual>
    <collision>
      <geometry>
        <mesh filename="package://mybot_description/meshes/shaft_simple.dae"/>
      </geometry>
    </collision>
    <inertial>
      <origin rpy="0 0 0" xyz="0.0 0.026065 0.0"/>
      <mass value="0.1"/>
      <inertia ixx="4.94e-05" ixy="0.0" ixz="0.0" iyy="6.11e-05" iyz="0.0" izz="4.94e-05"/>
    </inertial>
  </link>
  <joint name="joint_eixo_tracao_t1" type="continuous">
    <parent link="garra_tracao_t1"/>
    <child link="eixo_tracao_t1"/>
    <origin rpy="0 0 0" xyz="0.0 0.049 0.145"/>
    <axis xyz="0 1 0"/>
    <dynamics damping="0.7" friction="1.0" />
  </joint>
  <!-- T2 -->
  <link name="garra_tracao_t2">
    <visual>
      <geometry>
        <mesh filename="package://mybot_description/meshes/claw.dae"/>
      </geometry>
      <material name="grey"/>
      <origin rpy="0 0 0" xyz="0.0 0.012 0.0"/>

    </visual>
    <collision>
      <geometry>
        <box size="0.048 0.064 0.1851"/>
      </geometry>
      <origin rpy="0 0 0" xyz="0.0 0.017 0.09255"/>
    </collision>
    <inertial>
      <origin rpy="0 0 0" xyz="0.0 0.015953 0.116844"/>
      <mass value="0.22"/>
      <inertia ixx="0.000598" ixy="0.0" ixz="0.0" iyy="0.000866" iyz="0.000169" izz="0.000866"/>
    </inertial>
  </link>
  <joint name="joint_garra_tracao_t2" type="revolute">
    <parent link="tracao_t"/>
    <child link="garra_tracao_t2"/>
    <origin rpy="0 0 3.141592" xyz="0.1765 0.075 0.06985"/>
    <limit effort="1000.0" lower="-3.14" upper="3.14" velocity="0.5"/>
    <axis xyz="0 0 1"/>
  </joint>
  <!-- Eixo F2 -->
  <link name="eixo_tracao_t2">
    <visual>
      <geometry>
        <mesh filename="package://mybot_description/meshes/shaft_simple.dae"/>
      </geometry>
      <material name="grey"/>
      <!-- <origin rpy="0 0 0" xyz="0.0 0.012 0.025"/> -->
    </visual>
    <collision>
      <geometry>
        <mesh filename="package://mybot_description/meshes/shaft_simple.dae"/>
      </geometry>
    </collision>
    <inertial>
      <origin rpy="0 0 0" xyz="0.0 0.026065 0.0"/>
      <mass value="0.1"/>
      <inertia ixx="4.94e-05" ixy="0.0" ixz="0.0" iyy="6.11e-05" iyz="0.0" izz="4.94e-05"/>
    </inertial>
  </link>
  <joint name="joint_eixo_tracao_t2" type="continuous">
    <parent link="garra_tracao_t2"/>
    <child link="eixo_tracao_t2"/>
    <origin rpy="0 0 0" xyz="0.0 0.049 0.145"/>
    <axis xyz="0 1 0"/>
    <dynamics damping="0.7" friction="1.0" />
  </joint>
  <!-- SENSORES -->
  <!-- Hokuyo -->
  <!-- Posicao do Hokuyo (em relacao a junta 3)-->
  <!-- Posicao do sonar baixo (em relacao a junta 3)-->
  <!-- Posicao do sonar alto (em relacao a garra)-->
  <!-- Dimensoes do suporte do sonar alto -->
  <!-- Posicao do suporte do sonar alto -->
  <!-- Posicao do sonar de chao (em relacao ao base_link)-->
  <!-- Posicoes dos frames virtuais -->
  <!-- Apoio -->
  <!--<link name="laser" >
		<visual>
			<geometry>
				<mesh filename="package://mybot_description/meshes/hokuyo.dae"/>
			</geometry>
			<xacro:cor />
		</visual>
	</link>

	<joint name="hokuyo_base" type="fixed">
		<parent link="tracao_f" />
		<child link="laser" />
		<origin xyz="${x_hokuyo} ${y_hokuyo} ${z_hokuyo}" rpy="0 ${pi - pitch_angle_hokuyo} ${pi}" />
	</joint> -->
  <!-- Sonares -->
  <!-- <link name="obstacle_sonar_down">
    <visual>
      <geometry>
        <mesh filename="package://mybot_description/meshes/maxsonar.dae"/>
      </geometry>
      <material name="grey"/>


    </visual>
    <inertial>
      <mass value="1e-5"/>
      <origin rpy="0 0 0" xyz="0 0 0"/>
      <inertia ixx="1e-6" ixy="0" ixz="0" iyy="1e-6" iyz="0" izz="1e-6"/>
    </inertial>
  </link> -->
  <!-- <joint name="obstacle_sonar_down_base" type="fixed">
    <parent link="tracao_f"/>
    <child link="obstacle_sonar_down"/>
    <origin rpy="0 0 0" xyz="0.205 0.0 0.0569"/>
  </joint>
  <link name="obstacle_sonar_up">
    <visual>
      <geometry>
        <mesh filename="package://mybot_description/meshes/maxsonar.dae"/>
      </geometry>
      <material name="grey"/>


    </visual>
    <inertial>
      <mass value="1e-5"/>
      <origin rpy="0 0 0" xyz="0 0 0"/>
      <inertia ixx="1e-6" ixy="0" ixz="0" iyy="1e-6" iyz="0" izz="1e-6"/>
    </inertial>
    <visual>
      <geometry>
        <box size="0.005 0.07 0.0221"/>
      </geometry>
      <material name="grey"/>


      <origin rpy="0 0 0" xyz="-0.0025 -0.02395 0.0"/>
    </visual>
  </link> -->
  <!-- <joint name="obstacle_sonar_up_base" type="fixed">
    <parent link="garra_tracao_f2"/>
    <child link="obstacle_sonar_up"/>
    <origin rpy="0 0 0" xyz="0.024 0.075 0.19615"/>
  </joint> -->
  <!--
	<link name="ground_sonar" >
		<visual>
			<geometry>
				<mesh filename="package://mybot_description/meshes/groundsonar.dae"/>
			</geometry>
			<xacro:cor />
		</visual>
	</link>

	<joint name="ground_sonar_base" type="fixed">
		<parent link="base_link" />
		<child link="ground_sonar" />
		<origin xyz="${x_ground_sonar} ${w_eletr_ap/2 + y_ground_sonar} ${z_ground_sonar}" rpy="0 0 0" />
	</joint> -->
  <!-- FRAMES VIRTUAIS NO CABO -->
  <!-- Tracao -->
  <!--
	<link name="cabo_ap"/>
	<link name="cabo_tracao_f1"/>
	<link name="cabo_tracao_f2"/>
	<link name="cabo_tracao_t1"/>
	<link name="cabo_tracao_t2"/>

	<joint name="joint_cabo_ap" type="fixed">
		<parent link="base_link" />
		<child link="cabo_ap" />
		<origin xyz="${x_joint_cabo_ap} ${y_joint_cabo_ap} ${z_joint_cabo_ap + h_ap/2}" rpy="0 0 0" />
	</joint>

	<joint name="joint_cabo_tracao_f1" type="fixed">
		<parent link="tracao_f" />
		<child link="cabo_tracao_f1" />
		<origin xyz="${x_joint_garra_tracao1} ${y_joint_cabo_tracao} ${z_joint_cabo_tracao + h_tracao/2 + z_tracao}" rpy="0 0 0" />
	</joint>

	<joint name="joint_cabo_tracao_f2" type="fixed">
		<parent link="tracao_f" />
		<child link="cabo_tracao_f2" />
		<origin xyz="${x_joint_garra_tracao2} ${y_joint_cabo_tracao} ${z_joint_cabo_tracao + h_tracao/2 + z_tracao}" rpy="0 0 0" />
	</joint>

	<joint name="joint_cabo_tracao_t1" type="fixed">
		<parent link="tracao_t" />
		<child link="cabo_tracao_t1" />
		<origin xyz="${x_joint_garra_tracao1} ${y_joint_cabo_tracao} ${z_joint_cabo_tracao + h_tracao/2 + z_tracao}" rpy="0 0 0" />
	</joint>

	<joint name="joint_cabo_tracao_t2" type="fixed">
		<parent link="tracao_t" />
		<child link="cabo_tracao_t2" />
		<origin xyz="${x_joint_garra_tracao2} ${y_joint_cabo_tracao} ${z_joint_cabo_tracao + h_tracao/2 + z_tracao}" rpy="0 0 0" />
	</joint>-->
  <!-- ROS Control-->
  <!-- Juntas -->
  <transmission name="tran_joint_1f">
    <type>transmission_interface/SimpleTransmission</type>
    <joint name="joint1_f">
      <hardwareInterface>hardware_interface/EffortJointInterface</hardwareInterface>
    </joint>
    <actuator name="servo11">
      <hardwareInterface>EffortJointInterface</hardwareInterface>
      <mechanicalReduction>1</mechanicalReduction>
    </actuator>
  </transmission>
  <transmission name="tran_joint_2f">
    <type>transmission_interface/SimpleTransmission</type>
    <joint name="joint2_f">
      <hardwareInterface>hardware_interface/EffortJointInterface</hardwareInterface>
    </joint>
    <actuator name="servo13">
      <hardwareInterface>EffortJointInterface</hardwareInterface>
      <mechanicalReduction>1</mechanicalReduction>
    </actuator>
  </transmission>
  <transmission name="tran_joint_1t">
    <type>transmission_interface/SimpleTransmission</type>
    <joint name="joint1_t">
      <hardwareInterface>hardware_interface/EffortJointInterface</hardwareInterface>
    </joint>
    <actuator name="servo22">
      <hardwareInterface>EffortJointInterface</hardwareInterface>
      <mechanicalReduction>1</mechanicalReduction>
    </actuator>
  </transmission>
  <transmission name="tran_joint_2t">
    <type>transmission_interface/SimpleTransmission</type>
    <joint name="joint2_t">
      <hardwareInterface>hardware_interface/EffortJointInterface</hardwareInterface>
    </joint>
    <actuator name="servo24">
      <hardwareInterface>EffortJointInterface</hardwareInterface>
      <mechanicalReduction>1</mechanicalReduction>
    </actuator>
  </transmission>
  <!-- Garras -->
  <transmission name="tran_claw_c1">
    <type>transmission_interface/SimpleTransmission</type>
    <joint name="joint_garra_ap">
      <hardwareInterface>hardware_interface/EffortJointInterface</hardwareInterface>
    </joint>
    <actuator name="servo9">
      <hardwareInterface>EffortJointInterface</hardwareInterface>
      <mechanicalReduction>1</mechanicalReduction>
    </actuator>
  </transmission>
  <transmission name="tran_claw_f1">
    <type>transmission_interface/SimpleTransmission</type>
    <joint name="joint_garra_tracao_f1">
      <hardwareInterface>hardware_interface/EffortJointInterface</hardwareInterface>
    </joint>
    <actuator name="servo15">
      <hardwareInterface>EffortJointInterface</hardwareInterface>
      <mechanicalReduction>1</mechanicalReduction>
    </actuator>
  </transmission>
  <transmission name="tran_claw_f2">
    <type>transmission_interface/SimpleTransmission</type>
    <joint name="joint_garra_tracao_f2">
      <hardwareInterface>hardware_interface/EffortJointInterface</hardwareInterface>
    </joint>
    <actuator name="servo17">
      <hardwareInterface>EffortJointInterface</hardwareInterface>
      <mechanicalReduction>1</mechanicalReduction>
    </actuator>
  </transmission>
  <transmission name="tran_claw_t1">
    <type>transmission_interface/SimpleTransmission</type>
    <joint name="joint_garra_tracao_t1">
      <hardwareInterface>hardware_interface/EffortJointInterface</hardwareInterface>
    </joint>
    <actuator name="servo25">
      <hardwareInterface>EffortJointInterface</hardwareInterface>
      <mechanicalReduction>1</mechanicalReduction>
    </actuator>
  </transmission>
  <transmission name="tran_claw_t2">
    <type>transmission_interface/SimpleTransmission</type>
    <joint name="joint_garra_tracao_t2">
      <hardwareInterface>hardware_interface/EffortJointInterface</hardwareInterface>
    </joint>
    <actuator name="servo27">
      <hardwareInterface>EffortJointInterface</hardwareInterface>
      <mechanicalReduction>1</mechanicalReduction>
    </actuator>
  </transmission>
  <!-- Velocity Controllers -->
  <transmission name="tran_tracao_1c">
    <type>transmission_interface/SimpleTransmission</type>
    <joint name="joint_eixo_tracao_ap">
      <hardwareInterface>hardware_interface/VelocityJointInterface</hardwareInterface>
    </joint>
    <actuator name="servo10">
      <hardwareInterface>VelocityJointInterface</hardwareInterface>
      <mechanicalReduction>1</mechanicalReduction>
    </actuator>
  </transmission>
  <transmission name="tran_tracao_1f">
    <type>transmission_interface/SimpleTransmission</type>
    <joint name="joint_eixo_tracao_f1">
      <hardwareInterface>hardware_interface/VelocityJointInterface</hardwareInterface>
    </joint>
    <actuator name="servo16">
      <hardwareInterface>VelocityJointInterface</hardwareInterface>
      <mechanicalReduction>1</mechanicalReduction>
    </actuator>
  </transmission>
  <transmission name="tran_tracao_2f">
    <type>transmission_interface/SimpleTransmission</type>
    <joint name="joint_eixo_tracao_f2">
      <hardwareInterface>hardware_interface/VelocityJointInterface</hardwareInterface>
    </joint>
    <actuator name="servo18">
      <hardwareInterface>VelocityJointInterface</hardwareInterface>
      <mechanicalReduction>1</mechanicalReduction>
    </actuator>
  </transmission>
  <transmission name="tran_tracao_1t">
    <type>transmission_interface/SimpleTransmission</type>
    <joint name="joint_eixo_tracao_t1">
      <hardwareInterface>hardware_interface/VelocityJointInterface</hardwareInterface>
    </joint>
    <actuator name="servo26">
      <hardwareInterface>VelocityJointInterface</hardwareInterface>
      <mechanicalReduction>1</mechanicalReduction>
    </actuator>
  </transmission>
  <transmission name="tran_tracao_2t">
    <type>transmission_interface/SimpleTransmission</type>
    <joint name="joint_eixo_tracao_t2">
      <hardwareInterface>hardware_interface/VelocityJointInterface</hardwareInterface>
    </joint>
    <actuator name="servo28">
      <hardwareInterface>VelocityJointInterface</hardwareInterface>
      <mechanicalReduction>1</mechanicalReduction>
    </actuator>
  </transmission>
</robot>
